<?xml version="1.0" ?>
<!-- =================================================================================== -->
<!-- |    This document was autogenerated by xacro from urdf\combine.xacro.temp        | -->
<!-- |    EDITING THIS FILE BY HAND IS NOT RECOMMENDED                                 | -->
<!-- =================================================================================== -->
<robot xmlns:xacro="http://www.ros.org/wiki/xacro" name="combine">
  <material name="silver">
    <color rgba="0.700 0.700 0.700 1.000"/>
  </material>
  <transmission name="Revolute 16_tran">
    <type>transmission_interface/SimpleTransmission</type>
    <joint name="Revolute 16">
      <hardwareInterface>hardware_interface/EffortJointInterface</hardwareInterface>
    </joint>
    <actuator name="Revolute 16_actr">
      <hardwareInterface>hardware_interface/EffortJointInterface</hardwareInterface>
      <mechanicalReduction>1</mechanicalReduction>
    </actuator>
  </transmission>
  <transmission name="Revolute 17_tran">
    <type>transmission_interface/SimpleTransmission</type>
    <joint name="Revolute 17">
      <hardwareInterface>hardware_interface/EffortJointInterface</hardwareInterface>
    </joint>
    <actuator name="Revolute 17_actr">
      <hardwareInterface>hardware_interface/EffortJointInterface</hardwareInterface>
      <mechanicalReduction>1</mechanicalReduction>
    </actuator>
  </transmission>
  <transmission name="Revolute 18_tran">
    <type>transmission_interface/SimpleTransmission</type>
    <joint name="Revolute 18">
      <hardwareInterface>hardware_interface/EffortJointInterface</hardwareInterface>
    </joint>
    <actuator name="Revolute 18_actr">
      <hardwareInterface>hardware_interface/EffortJointInterface</hardwareInterface>
      <mechanicalReduction>1</mechanicalReduction>
    </actuator>
  </transmission>
  <transmission name="Revolute 19_tran">
    <type>transmission_interface/SimpleTransmission</type>
    <joint name="Revolute 19">
      <hardwareInterface>hardware_interface/EffortJointInterface</hardwareInterface>
    </joint>
    <actuator name="Revolute 19_actr">
      <hardwareInterface>hardware_interface/EffortJointInterface</hardwareInterface>
      <mechanicalReduction>1</mechanicalReduction>
    </actuator>
  </transmission>
  <transmission name="Revolute 25_tran">
    <type>transmission_interface/SimpleTransmission</type>
    <joint name="Revolute 25">
      <hardwareInterface>hardware_interface/EffortJointInterface</hardwareInterface>
    </joint>
    <actuator name="Revolute 25_actr">
      <hardwareInterface>hardware_interface/EffortJointInterface</hardwareInterface>
      <mechanicalReduction>1</mechanicalReduction>
    </actuator>
  </transmission>
  <transmission name="Revolute 28_tran">
    <type>transmission_interface/SimpleTransmission</type>
    <joint name="Revolute 28">
      <hardwareInterface>hardware_interface/EffortJointInterface</hardwareInterface>
    </joint>
    <actuator name="Revolute 28_actr">
      <hardwareInterface>hardware_interface/EffortJointInterface</hardwareInterface>
      <mechanicalReduction>1</mechanicalReduction>
    </actuator>
  </transmission>
  <!-- omitted .gazebo include -->
  <link name="base_link">
    <inertial>
      <origin xyz="2.6201367459841687 1.5370486071756042 0.09548127947996286" rpy="0 0 0"/>
      <mass value="40.85698587188984"/>
      <inertia ixx="0.201325" iyy="0.334676" izz="0.44481" ixy="4.2e-05" iyz="-0.00022" ixz="-0.004755"/>
    </inertial>
    <visual>
      <origin xyz="0 0 0" rpy="0 0 0"/>
      <geometry>
        <mesh filename="package://combine_description/meshes/base_link.stl" scale="0.001 0.001 0.001"/>
      </geometry>
      <material name="silver"/>
    </visual>
    <collision>
      <origin xyz="0 0 0" rpy="0 0 0"/>
      <geometry>
        <mesh filename="package://combine_description/meshes/base_link.stl" scale="0.001 0.001 0.001"/>
      </geometry>
    </collision>
  </link>
  <link name="Side_U_Bracket_Component1_v1_1">
    <inertial>
      <origin xyz="-0.002196073410680288 -1.5866330471681067e-08 -8.454843394226086e-05" rpy="0 0 0"/>
      <mass value="0.029510409828806653"/>
      <inertia ixx="1.1e-05" iyy="4e-06" izz="7e-06" ixy="0.0" iyz="-0.0" ixz="-0.0"/>
    </inertial>
    <visual>
      <origin xyz="-2.470346 -1.536923 -0.103876" rpy="0 0 0"/>
      <geometry>
        <mesh filename="package://combine_description/meshes/Side_U_Bracket_Component1_v1_1.stl" scale="0.001 0.001 0.001"/>
      </geometry>
      <material name="silver"/>
    </visual>
    <collision>
      <origin xyz="-2.470346 -1.536923 -0.103876" rpy="0 0 0"/>
      <geometry>
        <mesh filename="package://combine_description/meshes/Side_U_Bracket_Component1_v1_1.stl" scale="0.001 0.001 0.001"/>
      </geometry>
    </collision>
  </link>
  <link name="car_stand_v1_1">
    <inertial>
      <origin xyz="0.03989025557665071 -0.00250001586541293 -0.01795345148025415" rpy="0 0 0"/>
      <mass value="0.06574803361092377"/>
      <inertia ixx="1.6e-05" iyy="5.4e-05" izz="3.7e-05" ixy="0.0" iyz="-0.0" ixz="1.6e-05"/>
    </inertial>
    <visual>
      <origin xyz="-2.69969 -1.436923 -0.081538" rpy="0 0 0"/>
      <geometry>
        <mesh filename="package://combine_description/meshes/car_stand_v1_1.stl" scale="0.001 0.001 0.001"/>
      </geometry>
      <material name="silver"/>
    </visual>
    <collision>
      <origin xyz="-2.69969 -1.436923 -0.081538" rpy="0 0 0"/>
      <geometry>
        <mesh filename="package://combine_description/meshes/car_stand_v1_1.stl" scale="0.001 0.001 0.001"/>
      </geometry>
    </collision>
  </link>
  <link name="car_stand_v1_2">
    <inertial>
      <origin xyz="0.039890255576655154 0.0024999841345871854 -0.01795345148025415" rpy="0 0 0"/>
      <mass value="0.06574803361092377"/>
      <inertia ixx="1.6e-05" iyy="5.4e-05" izz="3.7e-05" ixy="0.0" iyz="0.0" ixz="1.6e-05"/>
    </inertial>
    <visual>
      <origin xyz="-2.69969 -1.636923 -0.081538" rpy="0 0 0"/>
      <geometry>
        <mesh filename="package://combine_description/meshes/car_stand_v1_2.stl" scale="0.001 0.001 0.001"/>
      </geometry>
      <material name="silver"/>
    </visual>
    <collision>
      <origin xyz="-2.69969 -1.636923 -0.081538" rpy="0 0 0"/>
      <geometry>
        <mesh filename="package://combine_description/meshes/car_stand_v1_2.stl" scale="0.001 0.001 0.001"/>
      </geometry>
    </collision>
  </link>
  <link name="car_stand_v1_3">
    <inertial>
      <origin xyz="-0.039890124337906396 -0.0025000158654198135 -0.017953451480257565" rpy="0 0 0"/>
      <mass value="0.06574803361092377"/>
      <inertia ixx="1.6e-05" iyy="5.4e-05" izz="3.7e-05" ixy="-0.0" iyz="-0.0" ixz="-1.6e-05"/>
    </inertial>
    <visual>
      <origin xyz="-2.541022 -1.436923 -0.081538" rpy="0 0 0"/>
      <geometry>
        <mesh filename="package://combine_description/meshes/car_stand_v1_3.stl" scale="0.001 0.001 0.001"/>
      </geometry>
      <material name="silver"/>
    </visual>
    <collision>
      <origin xyz="-2.541022 -1.436923 -0.081538" rpy="0 0 0"/>
      <geometry>
        <mesh filename="package://combine_description/meshes/car_stand_v1_3.stl" scale="0.001 0.001 0.001"/>
      </geometry>
    </collision>
  </link>
  <link name="car_stand_v1_4">
    <inertial>
      <origin xyz="-0.039890124337905064 0.002499984134580524 -0.017953451480259258" rpy="0 0 0"/>
      <mass value="0.06574803361092377"/>
      <inertia ixx="1.6e-05" iyy="5.4e-05" izz="3.7e-05" ixy="0.0" iyz="-0.0" ixz="-1.6e-05"/>
    </inertial>
    <visual>
      <origin xyz="-2.541022 -1.636923 -0.081538" rpy="0 0 0"/>
      <geometry>
        <mesh filename="package://combine_description/meshes/car_stand_v1_4.stl" scale="0.001 0.001 0.001"/>
      </geometry>
      <material name="silver"/>
    </visual>
    <collision>
      <origin xyz="-2.541022 -1.636923 -0.081538" rpy="0 0 0"/>
      <geometry>
        <mesh filename="package://combine_description/meshes/car_stand_v1_4.stl" scale="0.001 0.001 0.001"/>
      </geometry>
    </collision>
  </link>
  <link name="car_stand_2_v1__1__1">
    <inertial>
      <origin xyz="1.3964352207906927e-07 0.0024999841345731966 -3.022581173614536e-07" rpy="0 0 0"/>
      <mass value="0.02564919549902349"/>
      <inertia ixx="1e-06" iyy="3e-06" izz="1e-06" ixy="0.0" iyz="0.0" ixz="0.0"/>
    </inertial>
    <visual>
      <origin xyz="-2.476249 -1.436923 -0.03769" rpy="0 0 0"/>
      <geometry>
        <mesh filename="package://combine_description/meshes/car_stand_2_v1__1__1.stl" scale="0.001 0.001 0.001"/>
      </geometry>
      <material name="silver"/>
    </visual>
    <collision>
      <origin xyz="-2.476249 -1.436923 -0.03769" rpy="0 0 0"/>
      <geometry>
        <mesh filename="package://combine_description/meshes/car_stand_2_v1__1__1.stl" scale="0.001 0.001 0.001"/>
      </geometry>
    </collision>
  </link>
  <link name="car_stand_2_v1_1">
    <inertial>
      <origin xyz="1.3964352607587216e-07 -0.0025000158654255866 -3.0225811991496654e-07" rpy="0 0 0"/>
      <mass value="0.02564919549902349"/>
      <inertia ixx="1e-06" iyy="3e-06" izz="1e-06" ixy="0.0" iyz="0.0" ixz="-0.0"/>
    </inertial>
    <visual>
      <origin xyz="-2.476249 -1.636923 -0.03769" rpy="0 0 0"/>
      <geometry>
        <mesh filename="package://combine_description/meshes/car_stand_2_v1_1.stl" scale="0.001 0.001 0.001"/>
      </geometry>
      <material name="silver"/>
    </visual>
    <collision>
      <origin xyz="-2.476249 -1.636923 -0.03769" rpy="0 0 0"/>
      <geometry>
        <mesh filename="package://combine_description/meshes/car_stand_2_v1_1.stl" scale="0.001 0.001 0.001"/>
      </geometry>
    </collision>
  </link>
  <link name="car_stand_2_v1__1__2">
    <inertial>
      <origin xyz="-8.404806628448114e-09 0.0024999841345869633 -3.022581139544567e-07" rpy="0 0 0"/>
      <mass value="0.02564919549902349"/>
      <inertia ixx="1e-06" iyy="3e-06" izz="1e-06" ixy="-0.0" iyz="0.0" ixz="0.0"/>
    </inertial>
    <visual>
      <origin xyz="-2.764463 -1.436923 -0.03769" rpy="0 0 0"/>
      <geometry>
        <mesh filename="package://combine_description/meshes/car_stand_2_v1__1__2.stl" scale="0.001 0.001 0.001"/>
      </geometry>
      <material name="silver"/>
    </visual>
    <collision>
      <origin xyz="-2.764463 -1.436923 -0.03769" rpy="0 0 0"/>
      <geometry>
        <mesh filename="package://combine_description/meshes/car_stand_2_v1__1__2.stl" scale="0.001 0.001 0.001"/>
      </geometry>
    </collision>
  </link>
  <link name="car_stand_2_v1__1__3">
    <inertial>
      <origin xyz="-8.404802187556015e-09 -0.00250001586541293 -3.022581139544567e-07" rpy="0 0 0"/>
      <mass value="0.02564919549902349"/>
      <inertia ixx="1e-06" iyy="3e-06" izz="1e-06" ixy="-0.0" iyz="0.0" ixz="0.0"/>
    </inertial>
    <visual>
      <origin xyz="-2.764463 -1.636923 -0.03769" rpy="0 0 0"/>
      <geometry>
        <mesh filename="package://combine_description/meshes/car_stand_2_v1__1__3.stl" scale="0.001 0.001 0.001"/>
      </geometry>
      <material name="silver"/>
    </visual>
    <collision>
      <origin xyz="-2.764463 -1.636923 -0.03769" rpy="0 0 0"/>
      <geometry>
        <mesh filename="package://combine_description/meshes/car_stand_2_v1__1__3.stl" scale="0.001 0.001 0.001"/>
      </geometry>
    </collision>
  </link>
  <link name="car_wheel_v1_1">
    <inertial>
      <origin xyz="1.396435904688076e-07 -0.02381583259739828 -3.0225812865103396e-07" rpy="0 0 0"/>
      <mass value="0.7168827451003478"/>
      <inertia ixx="0.000271" iyy="0.000476" izz="0.000271" ixy="-0.0" iyz="0.0" ixz="0.0"/>
    </inertial>
    <visual>
      <origin xyz="-2.476249 -1.431923 -0.03769" rpy="0 0 0"/>
      <geometry>
        <mesh filename="package://combine_description/meshes/car_wheel_v1_1.stl" scale="0.001 0.001 0.001"/>
      </geometry>
      <material name="silver"/>
    </visual>
    <collision>
      <origin xyz="-2.476249 -1.431923 -0.03769" rpy="0 0 0"/>
      <geometry>
        <mesh filename="package://combine_description/meshes/car_wheel_v1_1.stl" scale="0.001 0.001 0.001"/>
      </geometry>
    </collision>
  </link>
  <link name="car_wheel_v1_2">
    <inertial>
      <origin xyz="-8.404738238709797e-09 -0.02381583259738429 -3.0225812480688674e-07" rpy="0 0 0"/>
      <mass value="0.7168827451003478"/>
      <inertia ixx="0.000271" iyy="0.000476" izz="0.000271" ixy="-0.0" iyz="0.0" ixz="0.0"/>
    </inertial>
    <visual>
      <origin xyz="-2.764463 -1.431923 -0.03769" rpy="0 0 0"/>
      <geometry>
        <mesh filename="package://combine_description/meshes/car_wheel_v1_2.stl" scale="0.001 0.001 0.001"/>
      </geometry>
      <material name="silver"/>
    </visual>
    <collision>
      <origin xyz="-2.764463 -1.431923 -0.03769" rpy="0 0 0"/>
      <geometry>
        <mesh filename="package://combine_description/meshes/car_wheel_v1_2.stl" scale="0.001 0.001 0.001"/>
      </geometry>
    </collision>
  </link>
  <link name="car_wheel_v1_3">
    <inertial>
      <origin xyz="1.3964357847839892e-07 0.02381580086654589 -3.0225810749434645e-07" rpy="0 0 0"/>
      <mass value="0.7168827451003478"/>
      <inertia ixx="0.000271" iyy="0.000476" izz="0.000271" ixy="0.0" iyz="0.0" ixz="-0.0"/>
    </inertial>
    <visual>
      <origin xyz="-2.476249 -1.641923 -0.03769" rpy="0 0 0"/>
      <geometry>
        <mesh filename="package://combine_description/meshes/car_wheel_v1_3.stl" scale="0.001 0.001 0.001"/>
      </geometry>
      <material name="silver"/>
    </visual>
    <collision>
      <origin xyz="-2.476249 -1.641923 -0.03769" rpy="0 0 0"/>
      <geometry>
        <mesh filename="package://combine_description/meshes/car_wheel_v1_3.stl" scale="0.001 0.001 0.001"/>
      </geometry>
    </collision>
  </link>
  <link name="car_wheel_v1_4">
    <inertial>
      <origin xyz="-8.404747564583204e-09 0.023815800866558545 -3.0225810280365417e-07" rpy="0 0 0"/>
      <mass value="0.7168827451003478"/>
      <inertia ixx="0.000271" iyy="0.000476" izz="0.000271" ixy="0.0" iyz="0.0" ixz="-0.0"/>
    </inertial>
    <visual>
      <origin xyz="-2.764463 -1.641923 -0.03769" rpy="0 0 0"/>
      <geometry>
        <mesh filename="package://combine_description/meshes/car_wheel_v1_4.stl" scale="0.001 0.001 0.001"/>
      </geometry>
      <material name="silver"/>
    </visual>
    <collision>
      <origin xyz="-2.764463 -1.641923 -0.03769" rpy="0 0 0"/>
      <geometry>
        <mesh filename="package://combine_description/meshes/car_wheel_v1_4.stl" scale="0.001 0.001 0.001"/>
      </geometry>
    </collision>
  </link>
  <link name="new_motor_v2_1">
    <inertial>
      <origin xyz="-0.007452162690622988 -0.022426766220087657 0.017654058215962137" rpy="0 0 0"/>
      <mass value="0.20364393858439991"/>
      <inertia ixx="5.1e-05" iyy="3.5e-05" izz="3e-05" ixy="-0.0" iyz="-0.0" ixz="-0.0"/>
    </inertial>
    <visual>
      <origin xyz="-2.463033 -1.557173 -0.086342" rpy="0 0 0"/>
      <geometry>
        <mesh filename="package://combine_description/meshes/new_motor_v2_1.stl" scale="0.001 0.001 0.001"/>
      </geometry>
      <material name="silver"/>
    </visual>
    <collision>
      <origin xyz="-2.463033 -1.557173 -0.086342" rpy="0 0 0"/>
      <geometry>
        <mesh filename="package://combine_description/meshes/new_motor_v2_1.stl" scale="0.001 0.001 0.001"/>
      </geometry>
    </collision>
  </link>
  <link name="big_U_self_v1_1">
    <inertial>
      <origin xyz="-9.278559600200964e-06 -1.5859400459561357e-08 0.02423730026333773" rpy="0 0 0"/>
      <mass value="0.04184744776648081"/>
      <inertia ixx="3.2e-05" iyy="1.1e-05" izz="2.4e-05" ixy="0.0" iyz="0.0" ixz="0.0"/>
    </inertial>
    <visual>
      <origin xyz="-2.455529 -1.537423 -0.113896" rpy="0 0 0"/>
      <geometry>
        <mesh filename="package://combine_description/meshes/big_U_self_v1_1.stl" scale="0.001 0.001 0.001"/>
      </geometry>
      <material name="silver"/>
    </visual>
    <collision>
      <origin xyz="-2.455529 -1.537423 -0.113896" rpy="0 0 0"/>
      <geometry>
        <mesh filename="package://combine_description/meshes/big_U_self_v1_1.stl" scale="0.001 0.001 0.001"/>
      </geometry>
    </collision>
  </link>
  <link name="small_U_self_v1_1">
    <inertial>
      <origin xyz="-3.362366400416761e-06 -1.5858258262113623e-08 0.008808887308101726" rpy="0 0 0"/>
      <mass value="0.024887279691899796"/>
      <inertia ixx="1e-05" iyy="3e-06" izz="9e-06" ixy="0.0" iyz="0.0" ixz="0.0"/>
    </inertial>
    <visual>
      <origin xyz="-2.455514 -1.537423 -0.153896" rpy="0 0 0"/>
      <geometry>
        <mesh filename="package://combine_description/meshes/small_U_self_v1_1.stl" scale="0.001 0.001 0.001"/>
      </geometry>
      <material name="silver"/>
    </visual>
    <collision>
      <origin xyz="-2.455514 -1.537423 -0.153896" rpy="0 0 0"/>
      <geometry>
        <mesh filename="package://combine_description/meshes/small_U_self_v1_1.stl" scale="0.001 0.001 0.001"/>
      </geometry>
    </collision>
  </link>
  <link name="new_motor_v2__1__1">
    <inertial>
      <origin xyz="4.231245224239899e-05 0.017373906255655047 0.017158219614772457" rpy="0 0 0"/>
      <mass value="0.2031909561032669"/>
      <inertia ixx="5.1e-05" iyy="3.4e-05" izz="3e-05" ixy="-0.0" iyz="-0.0" ixz="-0.0"/>
    </inertial>
    <visual>
      <origin xyz="-2.455509 -1.517173 -0.166996" rpy="0 0 0"/>
      <geometry>
        <mesh filename="package://combine_description/meshes/new_motor_v2__1__1.stl" scale="0.001 0.001 0.001"/>
      </geometry>
      <material name="silver"/>
    </visual>
    <collision>
      <origin xyz="-2.455509 -1.517173 -0.166996" rpy="0 0 0"/>
      <geometry>
        <mesh filename="package://combine_description/meshes/new_motor_v2__1__1.stl" scale="0.001 0.001 0.001"/>
      </geometry>
    </collision>
  </link>
  <link name="big_U_self_v1__1__1">
    <inertial>
      <origin xyz="0.02099481110863044 -1.5859162427744877e-08 -0.012111156182783689" rpy="0 0 0"/>
      <mass value="0.04184744776648075"/>
      <inertia ixx="2.6e-05" iyy="1.1e-05" izz="3e-05" ixy="0.0" iyz="0.0" ixz="4e-06"/>
    </inertial>
    <visual>
      <origin xyz="-2.455499 -1.537223 -0.194016" rpy="0 0 0"/>
      <geometry>
        <mesh filename="package://combine_description/meshes/big_U_self_v1__1__1.stl" scale="0.001 0.001 0.001"/>
      </geometry>
      <material name="silver"/>
    </visual>
    <collision>
      <origin xyz="-2.455499 -1.537223 -0.194016" rpy="0 0 0"/>
      <geometry>
        <mesh filename="package://combine_description/meshes/big_U_self_v1__1__1.stl" scale="0.001 0.001 0.001"/>
      </geometry>
    </collision>
  </link>
  <link name="grap_base_v1_1">
    <inertial>
      <origin xyz="0.012620205137387153 -1.5859888291558377e-08 -0.007280159470022279" rpy="0 0 0"/>
      <mass value="0.15189124788812738"/>
      <inertia ixx="8.7e-05" iyy="9.3e-05" izz="6.9e-05" ixy="-0.0" iyz="-0.0" ixz="-1.5e-05"/>
    </inertial>
    <visual>
      <origin xyz="-2.490147 -1.537223 -0.174029" rpy="0 0 0"/>
      <geometry>
        <mesh filename="package://combine_description/meshes/grap_base_v1_1.stl" scale="0.001 0.001 0.001"/>
      </geometry>
      <material name="silver"/>
    </visual>
    <collision>
      <origin xyz="-2.490147 -1.537223 -0.174029" rpy="0 0 0"/>
      <geometry>
        <mesh filename="package://combine_description/meshes/grap_base_v1_1.stl" scale="0.001 0.001 0.001"/>
      </geometry>
    </collision>
  </link>
  <link name="grap2_v1_1">
    <inertial>
      <origin xyz="0.027888213938345174 0.005587054721650553 -0.01737201961833626" rpy="0 0 0"/>
      <mass value="0.04062678118181498"/>
      <inertia ixx="1.1e-05" iyy="2.6e-05" izz="1.9e-05" ixy="0.0" iyz="-0.0" ixz="1.1e-05"/>
    </inertial>
    <visual>
      <origin xyz="-2.520898 -1.549723 -0.15629" rpy="0 0 0"/>
      <geometry>
        <mesh filename="package://combine_description/meshes/grap2_v1_1.stl" scale="0.001 0.001 0.001"/>
      </geometry>
      <material name="silver"/>
    </visual>
    <collision>
      <origin xyz="-2.520898 -1.549723 -0.15629" rpy="0 0 0"/>
      <geometry>
        <mesh filename="package://combine_description/meshes/grap2_v1_1.stl" scale="0.001 0.001 0.001"/>
      </geometry>
    </collision>
  </link>
  <link name="grap2_v1_Mirror___1__1">
    <inertial>
      <origin xyz="0.027888215302377617 -0.005587086454288848 -0.01737202064016871" rpy="0 0 0"/>
      <mass value="0.04062678364093099"/>
      <inertia ixx="1.1e-05" iyy="2.6e-05" izz="1.9e-05" ixy="-0.0" iyz="0.0" ixz="1.1e-05"/>
    </inertial>
    <visual>
      <origin xyz="-2.520898 -1.524723 -0.15629" rpy="0 0 0"/>
      <geometry>
        <mesh filename="package://combine_description/meshes/grap2_v1_Mirror___1__1.stl" scale="0.001 0.001 0.001"/>
      </geometry>
      <material name="silver"/>
    </visual>
    <collision>
      <origin xyz="-2.520898 -1.524723 -0.15629" rpy="0 0 0"/>
      <geometry>
        <mesh filename="package://combine_description/meshes/grap2_v1_Mirror___1__1.stl" scale="0.001 0.001 0.001"/>
      </geometry>
    </collision>
  </link>
  <joint name="Rigid 1" type="fixed">
    <origin xyz="2.470346 1.536923 0.103876" rpy="0 0 0"/>
    <parent link="base_link"/>
    <child link="Side_U_Bracket_Component1_v1_1"/>
  </joint>
  <joint name="Rigid 8" type="fixed">
    <origin xyz="2.69969 1.436923 0.081538" rpy="0 0 0"/>
    <parent link="base_link"/>
    <child link="car_stand_v1_1"/>
  </joint>
  <joint name="Rigid 9" type="fixed">
    <origin xyz="2.69969 1.636923 0.081538" rpy="0 0 0"/>
    <parent link="base_link"/>
    <child link="car_stand_v1_2"/>
  </joint>
  <joint name="Rigid 10" type="fixed">
    <origin xyz="2.541022 1.436923 0.081538" rpy="0 0 0"/>
    <parent link="base_link"/>
    <child link="car_stand_v1_3"/>
  </joint>
  <joint name="Rigid 11" type="fixed">
    <origin xyz="2.541022 1.636923 0.081538" rpy="0 0 0"/>
    <parent link="base_link"/>
    <child link="car_stand_v1_4"/>
  </joint>
  <joint name="Rigid 12" type="fixed">
    <origin xyz="-0.064773 0.0 -0.043848" rpy="0 0 0"/>
    <parent link="car_stand_v1_3"/>
    <child link="car_stand_2_v1__1__1"/>
  </joint>
  <joint name="Rigid 13" type="fixed">
    <origin xyz="-0.064773 0.0 -0.043848" rpy="0 0 0"/>
    <parent link="car_stand_v1_4"/>
    <child link="car_stand_2_v1_1"/>
  </joint>
  <joint name="Rigid 14" type="fixed">
    <origin xyz="0.064773 0.0 -0.043848" rpy="0 0 0"/>
    <parent link="car_stand_v1_1"/>
    <child link="car_stand_2_v1__1__2"/>
  </joint>
  <joint name="Rigid 15" type="fixed">
    <origin xyz="0.064773 0.0 -0.043848" rpy="0 0 0"/>
    <parent link="car_stand_v1_2"/>
    <child link="car_stand_2_v1__1__3"/>
  </joint>
  <joint name="Revolute 16" type="continuous">
    <origin xyz="-0.064773 -0.005 -0.043848" rpy="0 0 0"/>
    <parent link="car_stand_v1_3"/>
    <child link="car_wheel_v1_1"/>
    <axis xyz="0.0 -1.0 -0.0"/>
  </joint>
  <joint name="Revolute 17" type="continuous">
    <origin xyz="0.064773 -0.005 -0.043848" rpy="0 0 0"/>
    <parent link="car_stand_v1_1"/>
    <child link="car_wheel_v1_2"/>
    <axis xyz="0.0 1.0 0.0"/>
  </joint>
  <joint name="Revolute 18" type="continuous">
    <origin xyz="-0.064773 0.005 -0.043848" rpy="0 0 0"/>
    <parent link="car_stand_v1_4"/>
    <child link="car_wheel_v1_3"/>
    <axis xyz="-0.0 1.0 -0.0"/>
  </joint>
  <joint name="Revolute 19" type="continuous">
    <origin xyz="0.064773 0.005 -0.043848" rpy="0 0 0"/>
    <parent link="car_stand_v1_2"/>
    <child link="car_wheel_v1_4"/>
    <axis xyz="0.0 1.0 0.0"/>
  </joint>
  <joint name="Rigid 24" type="fixed">
    <origin xyz="-0.007313 0.02025 -0.017534" rpy="0 0 0"/>
    <parent link="Side_U_Bracket_Component1_v1_1"/>
    <child link="new_motor_v2_1"/>
  </joint>
  <joint name="Revolute 25" type="continuous">
    <origin xyz="-0.007504 -0.01975 0.027554" rpy="0 0 0"/>
    <parent link="new_motor_v2_1"/>
    <child link="big_U_self_v1_1"/>
    <axis xyz="-0.0 -1.0 0.0"/>
  </joint>
  <joint name="Rigid 26" type="fixed">
    <origin xyz="-1.5e-05 0.0 0.04" rpy="0 0 0"/>
    <parent link="big_U_self_v1_1"/>
    <child link="small_U_self_v1_1"/>
  </joint>
  <joint name="Rigid 27" type="fixed">
    <origin xyz="-5e-06 -0.02025 0.0131" rpy="0 0 0"/>
    <parent link="small_U_self_v1_1"/>
    <child link="new_motor_v2__1__1"/>
  </joint>
  <joint name="Revolute 28" type="continuous">
    <origin xyz="-1e-05 0.02005 0.02702" rpy="0 0 0"/>
    <parent link="new_motor_v2__1__1"/>
    <child link="big_U_self_v1__1__1"/>
    <axis xyz="-0.0 -1.0 0.0"/>
  </joint>
  <joint name="Rigid 29" type="fixed">
    <origin xyz="0.034648 0.0 -0.019987" rpy="0 0 0"/>
    <parent link="big_U_self_v1__1__1"/>
    <child link="grap_base_v1_1"/>
  </joint>
  <joint name="Rigid 32" type="fixed">
    <origin xyz="0.030751 0.0125 -0.017739" rpy="0 0 0"/>
    <parent link="grap_base_v1_1"/>
    <child link="grap2_v1_1"/>
  </joint>
  <joint name="Rigid 33" type="fixed">
    <origin xyz="0.030751 -0.0125 -0.017739" rpy="0 0 0"/>
    <parent link="grap_base_v1_1"/>
    <child link="grap2_v1_Mirror___1__1"/>
  </joint>
</robot>
