<?xml version="1.0" ?>
<!--===================================================================================-->
<!-- Autogenerated from v6.xacro -->
<!-- EDITING THIS FILE BY HAND IS NOT RECOMMENDED -->
<!--===================================================================================-->
<robot name="v6" xmlns:xacro="http://www.ros.org/wiki/xacro">
  <material name="silver">
    <color rgba="0.700 0.700 0.700 1.000"/>
  </material>
  <transmission name="Revolute 29_tran">
    <type>transmission_interface/SimpleTransmission</type>
    <joint name="Revolute 29">
      <hardwareInterface>hardware_interface/EffortJointInterface</hardwareInterface>
    </joint>
    <actuator name="Revolute 29_actr">
      <hardwareInterface>hardware_interface/EffortJointInterface</hardwareInterface>
      <mechanicalReduction>1</mechanicalReduction>
    </actuator>
  </transmission>
  <transmission name="Revolute 32_tran">
    <type>transmission_interface/SimpleTransmission</type>
    <joint name="Revolute 32">
      <hardwareInterface>hardware_interface/EffortJointInterface</hardwareInterface>
    </joint>
    <actuator name="Revolute 32_actr">
      <hardwareInterface>hardware_interface/EffortJointInterface</hardwareInterface>
      <mechanicalReduction>1</mechanicalReduction>
    </actuator>
  </transmission>
  <transmission name="Revolute 35_tran">
    <type>transmission_interface/SimpleTransmission</type>
    <joint name="Revolute 35">
      <hardwareInterface>hardware_interface/EffortJointInterface</hardwareInterface>
    </joint>
    <actuator name="Revolute 35_actr">
      <hardwareInterface>hardware_interface/EffortJointInterface</hardwareInterface>
      <mechanicalReduction>1</mechanicalReduction>
    </actuator>
  </transmission>
  <transmission name="Revolute 38_tran">
    <type>transmission_interface/SimpleTransmission</type>
    <joint name="Revolute 38">
      <hardwareInterface>hardware_interface/EffortJointInterface</hardwareInterface>
    </joint>
    <actuator name="Revolute 38_actr">
      <hardwareInterface>hardware_interface/EffortJointInterface</hardwareInterface>
      <mechanicalReduction>1</mechanicalReduction>
    </actuator>
  </transmission>
  <transmission name="Revolute 41_tran">
    <type>transmission_interface/SimpleTransmission</type>
    <joint name="Revolute 41">
      <hardwareInterface>hardware_interface/EffortJointInterface</hardwareInterface>
    </joint>
    <actuator name="Revolute 41_actr">
      <hardwareInterface>hardware_interface/EffortJointInterface</hardwareInterface>
      <mechanicalReduction>1</mechanicalReduction>
    </actuator>
  </transmission>
  <transmission name="Revolute 44_tran">
    <type>transmission_interface/SimpleTransmission</type>
    <joint name="Revolute 44">
      <hardwareInterface>hardware_interface/EffortJointInterface</hardwareInterface>
    </joint>
    <actuator name="Revolute 44_actr">
      <hardwareInterface>hardware_interface/EffortJointInterface</hardwareInterface>
      <mechanicalReduction>1</mechanicalReduction>
    </actuator>
  </transmission>
  <transmission name="Revolute 48_tran">
    <type>transmission_interface/SimpleTransmission</type>
    <joint name="Revolute 48">
      <hardwareInterface>hardware_interface/EffortJointInterface</hardwareInterface>
    </joint>
    <actuator name="Revolute 48_actr">
      <hardwareInterface>hardware_interface/EffortJointInterface</hardwareInterface>
      <mechanicalReduction>1</mechanicalReduction>
    </actuator>
  </transmission>
  <transmission name="Revolute 49_tran">
    <type>transmission_interface/SimpleTransmission</type>
    <joint name="Revolute 49">
      <hardwareInterface>hardware_interface/EffortJointInterface</hardwareInterface>
    </joint>
    <actuator name="Revolute 49_actr">
      <hardwareInterface>hardware_interface/EffortJointInterface</hardwareInterface>
      <mechanicalReduction>1</mechanicalReduction>
    </actuator>
  </transmission>
  <gazebo>
    <plugin filename="libgazebo_ros_control.so" name="control"/>
  </gazebo>
  <gazebo reference="base_link">
    <material>Gazebo/Silver</material>
    <mu1>0.2</mu1>
    <mu2>0.2</mu2>
    <selfCollide>true</selfCollide>
    <gravity>true</gravity>
  </gazebo>
  <gazebo reference="upper_blue_v1_1">
    <material>Gazebo/Silver</material>
    <mu1>0.2</mu1>
    <mu2>0.2</mu2>
    <selfCollide>true</selfCollide>
  </gazebo>
  <gazebo reference="upper_silver_v1_1">
    <material>Gazebo/Silver</material>
    <mu1>0.2</mu1>
    <mu2>0.2</mu2>
    <selfCollide>true</selfCollide>
  </gazebo>
  <gazebo reference="Side_U_Bracket_Component1_v2_1">
    <material>Gazebo/Silver</material>
    <mu1>0.2</mu1>
    <mu2>0.2</mu2>
    <selfCollide>true</selfCollide>
  </gazebo>
  <gazebo reference="new_motor_v2_1">
    <material>Gazebo/Silver</material>
    <mu1>0.2</mu1>
    <mu2>0.2</mu2>
    <selfCollide>true</selfCollide>
  </gazebo>
  <gazebo reference="car_stand_v2_1">
    <material>Gazebo/Silver</material>
    <mu1>0.2</mu1>
    <mu2>0.2</mu2>
    <selfCollide>true</selfCollide>
  </gazebo>
  <gazebo reference="car_stand_2_v2_v1_1">
    <material>Gazebo/Silver</material>
    <mu1>0.2</mu1>
    <mu2>0.2</mu2>
    <selfCollide>true</selfCollide>
  </gazebo>
  <gazebo reference="new_wheel_v1_1">
    <material>Gazebo/Silver</material>
    <mu1>0.2</mu1>
    <mu2>0.2</mu2>
    <selfCollide>true</selfCollide>
  </gazebo>
  <gazebo reference="car_stand_v2__1__1">
    <material>Gazebo/Silver</material>
    <mu1>0.2</mu1>
    <mu2>0.2</mu2>
    <selfCollide>true</selfCollide>
  </gazebo>
  <gazebo reference="car_stand_2_v2_v1__1__1">
    <material>Gazebo/Silver</material>
    <mu1>0.2</mu1>
    <mu2>0.2</mu2>
    <selfCollide>true</selfCollide>
  </gazebo>
  <gazebo reference="new_wheel_v1__1__1">
    <material>Gazebo/Silver</material>
    <mu1>0.2</mu1>
    <mu2>0.2</mu2>
    <selfCollide>true</selfCollide>
  </gazebo>
  <gazebo reference="car_stand_v2__2__1">
    <material>Gazebo/Silver</material>
    <mu1>0.2</mu1>
    <mu2>0.2</mu2>
    <selfCollide>true</selfCollide>
  </gazebo>
  <gazebo reference="car_stand_2_v2_v1__2__1">
    <material>Gazebo/Silver</material>
    <mu1>0.2</mu1>
    <mu2>0.2</mu2>
    <selfCollide>true</selfCollide>
  </gazebo>
  <gazebo reference="new_wheel_v1__2__1">
    <material>Gazebo/Silver</material>
    <mu1>0.2</mu1>
    <mu2>0.2</mu2>
    <selfCollide>true</selfCollide>
  </gazebo>
  <gazebo reference="car_stand_v2__2___1__1">
    <material>Gazebo/Silver</material>
    <mu1>0.2</mu1>
    <mu2>0.2</mu2>
    <selfCollide>true</selfCollide>
  </gazebo>
  <gazebo reference="car_stand_2_v2_v1__2___1__1">
    <material>Gazebo/Silver</material>
    <mu1>0.2</mu1>
    <mu2>0.2</mu2>
    <selfCollide>true</selfCollide>
  </gazebo>
  <gazebo reference="new_wheel_v1__2___1__1">
    <material>Gazebo/Silver</material>
    <mu1>0.2</mu1>
    <mu2>0.2</mu2>
    <selfCollide>true</selfCollide>
  </gazebo>
  <gazebo reference="big_U_self_v2_1">
    <material>Gazebo/Silver</material>
    <mu1>0.2</mu1>
    <mu2>0.2</mu2>
    <selfCollide>true</selfCollide>
  </gazebo>
  <gazebo reference="small_U_self_v3_v2_1">
    <material>Gazebo/Silver</material>
    <mu1>0.2</mu1>
    <mu2>0.2</mu2>
    <selfCollide>true</selfCollide>
  </gazebo>
  <gazebo reference="new_motor_v2__1__1">
    <material>Gazebo/Silver</material>
    <mu1>0.2</mu1>
    <mu2>0.2</mu2>
    <selfCollide>true</selfCollide>
  </gazebo>
  <gazebo reference="big_U_self_v2__1__1">
    <material>Gazebo/Silver</material>
    <mu1>0.2</mu1>
    <mu2>0.2</mu2>
    <selfCollide>true</selfCollide>
  </gazebo>
  <gazebo reference="grap_base_v1_1">
    <material>Gazebo/Silver</material>
    <mu1>0.2</mu1>
    <mu2>0.2</mu2>
    <selfCollide>true</selfCollide>
  </gazebo>
  <gazebo reference="grap2_v2_1">
    <material>Gazebo/Silver</material>
    <mu1>0.2</mu1>
    <mu2>0.2</mu2>
    <selfCollide>true</selfCollide>
  </gazebo>
  <gazebo reference="grap2_v2_Mirror__1">
    <material>Gazebo/Silver</material>
    <mu1>0.2</mu1>
    <mu2>0.2</mu2>
    <selfCollide>true</selfCollide>
  </gazebo>
  <link name="base_link">
    <inertial>
      <origin rpy="0 0 0" xyz="-0.11553126426818264 0.3343509101041353 0.06210098740688249"/>
      <mass value="37.56290080252228"/>
      <inertia ixx="0.155633" ixy="-0.0" ixz="0.000286" iyy="0.297492" iyz="0.0" izz="0.386843"/>
    </inertial>
    <visual>
      <origin rpy="0 0 0" xyz="0 0 0"/>
      <geometry>
        <mesh filename="package://v6_description/meshes/base_link.stl" scale="0.001 0.001 0.001"/>
      </geometry>
      <material name="silver"/>
    </visual>
    <collision>
      <origin rpy="0 0 0" xyz="0 0 0"/>
      <geometry>
        <mesh filename="package://v6_description/meshes/base_link.stl" scale="0.001 0.001 0.001"/>
      </geometry>
    </collision>
  </link>
  <link name="upper_blue_v1_1">
    <inertial>
      <origin rpy="0 0 0" xyz="0.0009557467788307433 0.0018926108398634733 -0.005546368824775272"/>
      <mass value="2.711654241548037"/>
      <inertia ixx="0.029512" ixy="4.7e-05" ixz="-1.7e-05" iyy="0.020937" iyz="-2e-05" izz="0.049756"/>
    </inertial>
    <visual>
      <origin rpy="0 0 0" xyz="0.114065 -0.334351 -0.110913"/>
      <geometry>
        <mesh filename="package://v6_description/meshes/upper_blue_v1_1.stl" scale="0.001 0.001 0.001"/>
      </geometry>
      <material name="silver"/>
    </visual>
    <collision>
      <origin rpy="0 0 0" xyz="0.114065 -0.334351 -0.110913"/>
      <geometry>
        <mesh filename="package://v6_description/meshes/upper_blue_v1_1.stl" scale="0.001 0.001 0.001"/>
      </geometry>
    </collision>
  </link>
  <link name="upper_silver_v1_1">
    <inertial>
      <origin rpy="0 0 0" xyz="-0.05397145103461684 0.12865565118005895 0.06340297559246169"/>
      <mass value="0.5824308278195107"/>
      <inertia ixx="0.00486" ixy="0.0" ixz="2.4e-05" iyy="0.001444" iyz="-0.0" izz="0.004712"/>
    </inertial>
    <visual>
      <origin rpy="0 0 0" xyz="-0.020935 -0.20677 -0.110239"/>
      <geometry>
        <mesh filename="package://v6_description/meshes/upper_silver_v1_1.stl" scale="0.001 0.001 0.001"/>
      </geometry>
      <material name="silver"/>
    </visual>
    <collision>
      <origin rpy="0 0 0" xyz="-0.020935 -0.20677 -0.110239"/>
      <geometry>
        <mesh filename="package://v6_description/meshes/upper_silver_v1_1.stl" scale="0.001 0.001 0.001"/>
      </geometry>
    </collision>
  </link>
  <link name="Side_U_Bracket_Component1_v2_1">
    <inertial>
      <origin rpy="0 0 0" xyz="-0.0021965017854476687 -8.991875011243877e-08 -8.398858180322377e-05"/>
      <mass value="0.02951040982880665"/>
      <inertia ixx="1.1e-05" ixy="0.0" ixz="-0.0" iyy="4e-06" iyz="-0.0" izz="7e-06"/>
    </inertial>
    <visual>
      <origin rpy="0 0 0" xyz="0.264049 -0.334351 -0.074934"/>
      <geometry>
        <mesh filename="package://v6_description/meshes/Side_U_Bracket_Component1_v2_1.stl" scale="0.001 0.001 0.001"/>
      </geometry>
      <material name="silver"/>
    </visual>
    <collision>
      <origin rpy="0 0 0" xyz="0.264049 -0.334351 -0.074934"/>
      <geometry>
        <mesh filename="package://v6_description/meshes/Side_U_Bracket_Component1_v2_1.stl" scale="0.001 0.001 0.001"/>
      </geometry>
    </collision>
  </link>
  <link name="new_motor_v2_1">
    <inertial>
      <origin rpy="0 0 0" xyz="-0.007329192500702741 -0.022426817930538745 0.017705283950517715"/>
      <mass value="0.2036448419526595"/>
      <inertia ixx="5.1e-05" ixy="-0.0" ixz="-0.0" iyy="3.5e-05" iyz="-0.0" izz="3e-05"/>
    </inertial>
    <visual>
      <origin rpy="0 0 0" xyz="0.271362 -0.354601 -0.057401"/>
      <geometry>
        <mesh filename="package://v6_description/meshes/new_motor_v2_1.stl" scale="0.001 0.001 0.001"/>
      </geometry>
      <material name="silver"/>
    </visual>
    <collision>
      <origin rpy="0 0 0" xyz="0.271362 -0.354601 -0.057401"/>
      <geometry>
        <mesh filename="package://v6_description/meshes/new_motor_v2_1.stl" scale="0.001 0.001 0.001"/>
      </geometry>
    </collision>
  </link>
  <link name="car_stand_v2_1">
    <inertial>
      <origin rpy="0 0 0" xyz="0.03988982720191274 -0.0025000899185844416 -0.017953891628120888"/>
      <mass value="0.06574803361092448"/>
      <inertia ixx="1.6e-05" ixy="0.0" ixz="1.6e-05" iyy="5.4e-05" iyz="0.0" izz="3.7e-05"/>
    </inertial>
    <visual>
      <origin rpy="0 0 0" xyz="0.034705 -0.234351 -0.052597"/>
      <geometry>
        <mesh filename="package://v6_description/meshes/car_stand_v2_1.stl" scale="0.001 0.001 0.001"/>
      </geometry>
      <material name="silver"/>
    </visual>
    <collision>
      <origin rpy="0 0 0" xyz="0.034705 -0.234351 -0.052597"/>
      <geometry>
        <mesh filename="package://v6_description/meshes/car_stand_v2_1.stl" scale="0.001 0.001 0.001"/>
      </geometry>
    </collision>
  </link>
  <link name="car_stand_2_v2_v1_1">
    <inertial>
      <origin rpy="0 0 0" xyz="-0.008838436779542623 0.0024999100814157293 -0.008838742405980921"/>
      <mass value="0.025649195499023388"/>
      <inertia ixx="1e-06" ixy="0.0" ixz="0.0" iyy="3e-06" iyz="0.0" izz="1e-06"/>
    </inertial>
    <visual>
      <origin rpy="0 0 0" xyz="-0.038906 -0.234351 -0.017587"/>
      <geometry>
        <mesh filename="package://v6_description/meshes/car_stand_2_v2_v1_1.stl" scale="0.001 0.001 0.001"/>
      </geometry>
      <material name="silver"/>
    </visual>
    <collision>
      <origin rpy="0 0 0" xyz="-0.038906 -0.234351 -0.017587"/>
      <geometry>
        <mesh filename="package://v6_description/meshes/car_stand_2_v2_v1_1.stl" scale="0.001 0.001 0.001"/>
      </geometry>
    </collision>
  </link>
  <link name="new_wheel_v1_1">
    <inertial>
      <origin rpy="0 0 0" xyz="-7.661286367220688e-07 -0.03633722962657118 1.709065836411755e-06"/>
      <mass value="2.7644063382593123"/>
      <inertia ixx="0.002173" ixy="-0.0" ixz="0.0" iyy="0.003475" iyz="-0.0" izz="0.002173"/>
    </inertial>
    <visual>
      <origin rpy="0 0 0" xyz="-0.030068 -0.229351 -0.008748"/>
      <geometry>
        <mesh filename="package://v6_description/meshes/new_wheel_v1_1.stl" scale="0.001 0.001 0.001"/>
      </geometry>
      <material name="silver"/>
    </visual>
    <collision>
      <origin rpy="0 0 0" xyz="-0.030068 -0.229351 -0.008748"/>
      <geometry>
        <mesh filename="package://v6_description/meshes/new_wheel_v1_1.stl" scale="0.001 0.001 0.001"/>
      </geometry>
    </collision>
  </link>
  <link name="car_stand_v2__1__1">
    <inertial>
      <origin rpy="0 0 0" xyz="0.03988982720191739 0.0024999100814168673 -0.017953891628120867"/>
      <mass value="0.06574803361092448"/>
      <inertia ixx="1.6e-05" ixy="0.0" ixz="1.6e-05" iyy="5.4e-05" iyz="0.0" izz="3.7e-05"/>
    </inertial>
    <visual>
      <origin rpy="0 0 0" xyz="0.034705 -0.434351 -0.052597"/>
      <geometry>
        <mesh filename="package://v6_description/meshes/car_stand_v2__1__1.stl" scale="0.001 0.001 0.001"/>
      </geometry>
      <material name="silver"/>
    </visual>
    <collision>
      <origin rpy="0 0 0" xyz="0.034705 -0.434351 -0.052597"/>
      <geometry>
        <mesh filename="package://v6_description/meshes/car_stand_v2__1__1.stl" scale="0.001 0.001 0.001"/>
      </geometry>
    </collision>
  </link>
  <link name="car_stand_2_v2_v1__1__1">
    <inertial>
      <origin rpy="0 0 0" xyz="-0.008838436779537981 -0.002500089918583026 -0.008838742405980895"/>
      <mass value="0.025649195499023388"/>
      <inertia ixx="1e-06" ixy="-0.0" ixz="0.0" iyy="3e-06" iyz="0.0" izz="1e-06"/>
    </inertial>
    <visual>
      <origin rpy="0 0 0" xyz="-0.038906 -0.434351 -0.017587"/>
      <geometry>
        <mesh filename="package://v6_description/meshes/car_stand_2_v2_v1__1__1.stl" scale="0.001 0.001 0.001"/>
      </geometry>
      <material name="silver"/>
    </visual>
    <collision>
      <origin rpy="0 0 0" xyz="-0.038906 -0.434351 -0.017587"/>
      <geometry>
        <mesh filename="package://v6_description/meshes/car_stand_2_v2_v1__1__1.stl" scale="0.001 0.001 0.001"/>
      </geometry>
    </collision>
  </link>
  <link name="new_wheel_v1__1__1">
    <inertial>
      <origin rpy="0 0 0" xyz="-7.66128632066071e-07 0.036337049789403775 -1.1938777991337551e-06"/>
      <mass value="2.7644063382593123"/>
      <inertia ixx="0.002173" ixy="0.0" ixz="-0.0" iyy="0.003475" iyz="-0.0" izz="0.002173"/>
    </inertial>
    <visual>
      <origin rpy="0 0 0" xyz="-0.030068 -0.439351 -0.008748"/>
      <geometry>
        <mesh filename="package://v6_description/meshes/new_wheel_v1__1__1.stl" scale="0.001 0.001 0.001"/>
      </geometry>
      <material name="silver"/>
    </visual>
    <collision>
      <origin rpy="0 0 0" xyz="-0.030068 -0.439351 -0.008748"/>
      <geometry>
        <mesh filename="package://v6_description/meshes/new_wheel_v1__1__1.stl" scale="0.001 0.001 0.001"/>
      </geometry>
    </collision>
  </link>
  <link name="car_stand_v2__2__1">
    <inertial>
      <origin rpy="0 0 0" xyz="-0.039890552712641136 -0.002500089918581444 -0.01795389162812419"/>
      <mass value="0.06574803361092448"/>
      <inertia ixx="1.6e-05" ixy="0.0" ixz="-1.6e-05" iyy="5.4e-05" iyz="-0.0" izz="3.7e-05"/>
    </inertial>
    <visual>
      <origin rpy="0 0 0" xyz="0.193373 -0.234351 -0.052597"/>
      <geometry>
        <mesh filename="package://v6_description/meshes/car_stand_v2__2__1.stl" scale="0.001 0.001 0.001"/>
      </geometry>
      <material name="silver"/>
    </visual>
    <collision>
      <origin rpy="0 0 0" xyz="0.193373 -0.234351 -0.052597"/>
      <geometry>
        <mesh filename="package://v6_description/meshes/car_stand_v2__2__1.stl" scale="0.001 0.001 0.001"/>
      </geometry>
    </collision>
  </link>
  <link name="car_stand_2_v2_v1__2__1">
    <inertial>
      <origin rpy="0 0 0" xyz="0.00883871126878566 0.0024999100814186437 -0.008838742405986177"/>
      <mass value="0.025649195499023388"/>
      <inertia ixx="1e-06" ixy="0.0" ixz="0.0" iyy="3e-06" iyz="-0.0" izz="1e-06"/>
    </inertial>
    <visual>
      <origin rpy="0 0 0" xyz="0.266985 -0.234351 -0.017587"/>
      <geometry>
        <mesh filename="package://v6_description/meshes/car_stand_2_v2_v1__2__1.stl" scale="0.001 0.001 0.001"/>
      </geometry>
      <material name="silver"/>
    </visual>
    <collision>
      <origin rpy="0 0 0" xyz="0.266985 -0.234351 -0.017587"/>
      <geometry>
        <mesh filename="package://v6_description/meshes/car_stand_2_v2_v1__2__1.stl" scale="0.001 0.001 0.001"/>
      </geometry>
    </collision>
  </link>
  <link name="new_wheel_v1__2__1">
    <inertial>
      <origin rpy="0 0 0" xyz="-6.180803067135088e-07 -0.03633722962656821 1.7090658331400665e-06"/>
      <mass value="2.7644063382593123"/>
      <inertia ixx="0.002173" ixy="-0.0" ixz="0.0" iyy="0.003475" iyz="-0.0" izz="0.002173"/>
    </inertial>
    <visual>
      <origin rpy="0 0 0" xyz="0.258146 -0.229351 -0.008748"/>
      <geometry>
        <mesh filename="package://v6_description/meshes/new_wheel_v1__2__1.stl" scale="0.001 0.001 0.001"/>
      </geometry>
      <material name="silver"/>
    </visual>
    <collision>
      <origin rpy="0 0 0" xyz="0.258146 -0.229351 -0.008748"/>
      <geometry>
        <mesh filename="package://v6_description/meshes/new_wheel_v1__2__1.stl" scale="0.001 0.001 0.001"/>
      </geometry>
    </collision>
  </link>
  <link name="car_stand_v2__2___1__1">
    <inertial>
      <origin rpy="0 0 0" xyz="-0.02389055271263707 0.002499910081420531 -0.017953891628124496"/>
      <mass value="0.06574803361092448"/>
      <inertia ixx="1.6e-05" ixy="0.0" ixz="-1.6e-05" iyy="5.4e-05" iyz="0.0" izz="3.7e-05"/>
    </inertial>
    <visual>
      <origin rpy="0 0 0" xyz="0.209373 -0.434351 -0.052597"/>
      <geometry>
        <mesh filename="package://v6_description/meshes/car_stand_v2__2___1__1.stl" scale="0.001 0.001 0.001"/>
      </geometry>
      <material name="silver"/>
    </visual>
    <collision>
      <origin rpy="0 0 0" xyz="0.209373 -0.434351 -0.052597"/>
      <geometry>
        <mesh filename="package://v6_description/meshes/car_stand_v2__2___1__1.stl" scale="0.001 0.001 0.001"/>
      </geometry>
    </collision>
  </link>
  <link name="car_stand_2_v2_v1__2___1__1">
    <inertial>
      <origin rpy="0 0 0" xyz="0.008838711268789712 -0.0025000899185792513 -0.008838742405986496"/>
      <mass value="0.025649195499023388"/>
      <inertia ixx="1e-06" ixy="0.0" ixz="0.0" iyy="3e-06" iyz="0.0" izz="1e-06"/>
    </inertial>
    <visual>
      <origin rpy="0 0 0" xyz="0.266985 -0.434351 -0.017587"/>
      <geometry>
        <mesh filename="package://v6_description/meshes/car_stand_2_v2_v1__2___1__1.stl" scale="0.001 0.001 0.001"/>
      </geometry>
      <material name="silver"/>
    </visual>
    <collision>
      <origin rpy="0 0 0" xyz="0.266985 -0.434351 -0.017587"/>
      <geometry>
        <mesh filename="package://v6_description/meshes/car_stand_2_v2_v1__2___1__1.stl" scale="0.001 0.001 0.001"/>
      </geometry>
    </collision>
  </link>
  <link name="new_wheel_v1__2___1__1">
    <inertial>
      <origin rpy="0 0 0" xyz="-6.180803027167059e-07 0.036337049789407494 -1.1938778027593272e-06"/>
      <mass value="2.7644063382593123"/>
      <inertia ixx="0.002173" ixy="0.0" ixz="-0.0" iyy="0.003475" iyz="-0.0" izz="0.002173"/>
    </inertial>
    <visual>
      <origin rpy="0 0 0" xyz="0.258146 -0.439351 -0.008748"/>
      <geometry>
        <mesh filename="package://v6_description/meshes/new_wheel_v1__2___1__1.stl" scale="0.001 0.001 0.001"/>
      </geometry>
      <material name="silver"/>
    </visual>
    <collision>
      <origin rpy="0 0 0" xyz="0.258146 -0.439351 -0.008748"/>
      <geometry>
        <mesh filename="package://v6_description/meshes/new_wheel_v1__2___1__1.stl" scale="0.001 0.001 0.001"/>
      </geometry>
    </collision>
  </link>
  <link name="big_U_self_v2_1">
    <inertial>
      <origin rpy="0 0 0" xyz="-0.02423767526178927 -8.991950056769227e-08 -8.853660350069403e-06"/>
      <mass value="0.041847447766480805"/>
      <inertia ixx="2.4e-05" ixy="0.0" ixz="-0.0" iyy="1.1e-05" iyz="-0.0" izz="3.2e-05"/>
    </inertial>
    <visual>
      <origin rpy="0 0 0" xyz="0.278674 -0.334851 -0.085006"/>
      <geometry>
        <mesh filename="package://v6_description/meshes/big_U_self_v2_1.stl" scale="0.001 0.001 0.001"/>
      </geometry>
      <material name="silver"/>
    </visual>
    <collision>
      <origin rpy="0 0 0" xyz="0.278674 -0.334851 -0.085006"/>
      <geometry>
        <mesh filename="package://v6_description/meshes/big_U_self_v2_1.stl" scale="0.001 0.001 0.001"/>
      </geometry>
    </collision>
  </link>
  <link name="small_U_self_v3_v2_1">
    <inertial>
      <origin rpy="0 0 0" xyz="-0.009287648733685094 -0.0005384482220820441 -3.1143207411127305e-06"/>
      <mass value="0.025534175468152884"/>
      <inertia ixx="9e-06" ixy="-0.0" ixz="-0.0" iyy="3e-06" iyz="-0.0" izz="1e-05"/>
    </inertial>
    <visual>
      <origin rpy="0 0 0" xyz="0.318674 -0.334851 -0.084991"/>
      <geometry>
        <mesh filename="package://v6_description/meshes/small_U_self_v3_v2_1.stl" scale="0.001 0.001 0.001"/>
      </geometry>
      <material name="silver"/>
    </visual>
    <collision>
      <origin rpy="0 0 0" xyz="0.318674 -0.334851 -0.084991"/>
      <geometry>
        <mesh filename="package://v6_description/meshes/small_U_self_v3_v2_1.stl" scale="0.001 0.001 0.001"/>
      </geometry>
    </collision>
  </link>
  <link name="new_motor_v2__1__1">
    <inertial>
      <origin rpy="0 0 0" xyz="-0.0026535935407322464 0.02242666042984809 -0.007555050277332054"/>
      <mass value="0.20364393858439991"/>
      <inertia ixx="3e-05" ixy="-0.0" ixz="-0.0" iyy="3.5e-05" iyz="-0.0" izz="5.1e-05"/>
    </inertial>
    <visual>
      <origin rpy="0 0 0" xyz="0.346177 -0.314601 -0.092481"/>
      <geometry>
        <mesh filename="package://v6_description/meshes/new_motor_v2__1__1.stl" scale="0.001 0.001 0.001"/>
      </geometry>
      <material name="silver"/>
    </visual>
    <collision>
      <origin rpy="0 0 0" xyz="0.346177 -0.314601 -0.092481"/>
      <geometry>
        <mesh filename="package://v6_description/meshes/new_motor_v2__1__1.stl" scale="0.001 0.001 0.001"/>
      </geometry>
    </collision>
  </link>
  <link name="big_U_self_v2__1__1">
    <inertial>
      <origin rpy="0 0 0" xyz="-9.12643416350889e-06 -8.993477979002407e-08 0.024237117404991515"/>
      <mass value="0.04184744776647988"/>
      <inertia ixx="3.2e-05" ixy="0.0" ixz="0.0" iyy="1.1e-05" iyz="-0.0" izz="2.4e-05"/>
    </inertial>
    <visual>
      <origin rpy="0 0 0" xyz="0.358674 -0.334351 -0.084977"/>
      <geometry>
        <mesh filename="package://v6_description/meshes/big_U_self_v2__1__1.stl" scale="0.001 0.001 0.001"/>
      </geometry>
      <material name="silver"/>
    </visual>
    <collision>
      <origin rpy="0 0 0" xyz="0.358674 -0.334351 -0.084977"/>
      <geometry>
        <mesh filename="package://v6_description/meshes/big_U_self_v2__1__1.stl" scale="0.001 0.001 0.001"/>
      </geometry>
    </collision>
  </link>
  <link name="grap_base_v1_1">
    <inertial>
      <origin rpy="0 0 0" xyz="5.0604957804400996e-05 -8.993024042114328e-08 0.01574867865416396"/>
      <mass value="0.16096668074514336"/>
      <inertia ixx="6.6e-05" ixy="-0.0" ixz="-0.0" iyy="9.8e-05" iyz="-0.0" izz="9.8e-05"/>
    </inertial>
    <visual>
      <origin rpy="0 0 0" xyz="0.358689 -0.334351 -0.124977"/>
      <geometry>
        <mesh filename="package://v6_description/meshes/grap_base_v1_1.stl" scale="0.001 0.001 0.001"/>
      </geometry>
      <material name="silver"/>
    </visual>
    <collision>
      <origin rpy="0 0 0" xyz="0.358689 -0.334351 -0.124977"/>
      <geometry>
        <mesh filename="package://v6_description/meshes/grap_base_v1_1.stl" scale="0.001 0.001 0.001"/>
      </geometry>
    </collision>
  </link>
  <link name="grap2_v2_1">
    <inertial>
      <origin rpy="0 0 0" xyz="0.0011003881163325624 0.005586980664124386 0.0328376081661004"/>
      <mass value="0.040626783640930766"/>
      <inertia ixx="2.7e-05" ixy="0.0" ixz="-2e-06" iyy="2.6e-05" iyz="0.0" izz="3e-06"/>
    </inertial>
    <visual>
      <origin rpy="0 0 0" xyz="0.358702 -0.346851 -0.160477"/>
      <geometry>
        <mesh filename="package://v6_description/meshes/grap2_v2_1.stl" scale="0.001 0.001 0.001"/>
      </geometry>
      <material name="silver"/>
    </visual>
    <collision>
      <origin rpy="0 0 0" xyz="0.358702 -0.346851 -0.160477"/>
      <geometry>
        <mesh filename="package://v6_description/meshes/grap2_v2_1.stl" scale="0.001 0.001 0.001"/>
      </geometry>
    </collision>
  </link>
  <link name="grap2_v2_Mirror__1">
    <inertial>
      <origin rpy="0 0 0" xyz="0.0011003881213494937 -0.0055871605220216836 0.03283760816689857"/>
      <mass value="0.04062678364093079"/>
      <inertia ixx="2.7e-05" ixy="-0.0" ixz="-2e-06" iyy="2.6e-05" iyz="-0.0" izz="3e-06"/>
    </inertial>
    <visual>
      <origin rpy="0 0 0" xyz="0.358702 -0.321851 -0.160477"/>
      <geometry>
        <mesh filename="package://v6_description/meshes/grap2_v2_Mirror__1.stl" scale="0.001 0.001 0.001"/>
      </geometry>
      <material name="silver"/>
    </visual>
    <collision>
      <origin rpy="0 0 0" xyz="0.358702 -0.321851 -0.160477"/>
      <geometry>
        <mesh filename="package://v6_description/meshes/grap2_v2_Mirror__1.stl" scale="0.001 0.001 0.001"/>
      </geometry>
    </collision>
  </link>
  <joint name="Rigid 1" type="fixed">
    <origin rpy="0 0 0" xyz="-0.114065 0.334351 0.110913"/>
    <parent link="base_link"/>
    <child link="upper_blue_v1_1"/>
  </joint>
  <joint name="Rigid 2" type="fixed">
    <origin rpy="0 0 0" xyz="0.135 -0.127581 -0.000674"/>
    <parent link="upper_blue_v1_1"/>
    <child link="upper_silver_v1_1"/>
  </joint>
  <joint name="Rigid 3" type="fixed">
    <origin rpy="0 0 0" xyz="-0.264049 0.334351 0.074934"/>
    <parent link="base_link"/>
    <child link="Side_U_Bracket_Component1_v2_1"/>
  </joint>
  <joint name="Rigid 16" type="fixed">
    <origin rpy="0 0 0" xyz="-0.007313 0.02025 -0.017533"/>
    <parent link="Side_U_Bracket_Component1_v2_1"/>
    <child link="new_motor_v2_1"/>
  </joint>
  <joint name="Rigid 27" type="fixed">
    <origin rpy="0 0 0" xyz="-0.034705 0.234351 0.052597"/>
    <parent link="base_link"/>
    <child link="car_stand_v2_1"/>
  </joint>
  <joint name="Rigid 28" type="fixed">
    <origin rpy="0 0 0" xyz="0.073611 0.0 -0.03501"/>
    <parent link="car_stand_v2_1"/>
    <child link="car_stand_2_v2_v1_1"/>
  </joint>
  <joint name="Revolute 29" type="continuous">
    <origin rpy="0 0 0" xyz="0.064773 -0.005 -0.043849"/>
    <parent link="car_stand_v2_1"/>
    <child link="new_wheel_v1_1"/>
    <axis xyz="0.0 1.0 0.0"/>
  </joint>
  <joint name="Rigid 30" type="fixed">
    <origin rpy="0 0 0" xyz="-0.034705 0.434351 0.052597"/>
    <parent link="base_link"/>
    <child link="car_stand_v2__1__1"/>
  </joint>
  <joint name="Rigid 31" type="fixed">
    <origin rpy="0 0 0" xyz="0.073611 0.0 -0.03501"/>
    <parent link="car_stand_v2__1__1"/>
    <child link="car_stand_2_v2_v1__1__1"/>
  </joint>
  <joint name="Revolute 32" type="continuous">
    <origin rpy="0 0 0" xyz="0.064773 0.005 -0.043849"/>
    <parent link="car_stand_v2__1__1"/>
    <child link="new_wheel_v1__1__1"/>
    <axis xyz="0.0 1.0 0.0"/>
  </joint>
  <joint name="Rigid 33" type="fixed">
    <origin rpy="0 0 0" xyz="-0.193373 0.234351 0.052597"/>
    <parent link="base_link"/>
    <child link="car_stand_v2__2__1"/>
  </joint>
  <joint name="Rigid 34" type="fixed">
    <origin rpy="0 0 0" xyz="-0.073612 0.0 -0.03501"/>
    <parent link="car_stand_v2__2__1"/>
    <child link="car_stand_2_v2_v1__2__1"/>
  </joint>
  <joint name="Revolute 35" type="continuous">
    <origin rpy="0 0 0" xyz="-0.064773 -0.005 -0.043849"/>
    <parent link="car_stand_v2__2__1"/>
    <child link="new_wheel_v1__2__1"/>
    <axis xyz="0.0 -1.0 -0.0"/>
  </joint>
  <joint name="Rigid 36" type="fixed">
    <origin rpy="0 0 0" xyz="-0.209373 0.434351 0.052597"/>
    <parent link="base_link"/>
    <child link="car_stand_v2__2___1__1"/>
  </joint>
  <joint name="Rigid 37" type="fixed">
    <origin rpy="0 0 0" xyz="-0.057612 0.0 -0.03501"/>
    <parent link="car_stand_v2__2___1__1"/>
    <child link="car_stand_2_v2_v1__2___1__1"/>
  </joint>
  <joint name="Revolute 38" type="continuous">
    <origin rpy="0 0 0" xyz="-0.048773 0.005 -0.043849"/>
    <parent link="car_stand_v2__2___1__1"/>
    <child link="new_wheel_v1__2___1__1"/>
    <axis xyz="-0.0 1.0 0.0"/>
  </joint>
  <joint name="Revolute 41" type="continuous">
    <origin rpy="0 0 0" xyz="-0.007312 -0.01975 0.027605"/>
    <parent link="new_motor_v2_1"/>
    <child link="big_U_self_v2_1"/>
    <axis xyz="0.0 -1.0 0.0"/>
  </joint>
  <joint name="Rigid 42" type="fixed">
    <origin rpy="0 0 0" xyz="-0.04 0.0 -1.5e-05"/>
    <parent link="big_U_self_v2_1"/>
    <child link="small_U_self_v3_v2_1"/>
  </joint>
  <joint name="Rigid 43" type="fixed">
    <origin rpy="0 0 0" xyz="-0.027503 -0.02025 0.00749"/>
    <parent link="small_U_self_v3_v2_1"/>
    <child link="new_motor_v2__1__1"/>
  </joint>
  <joint name="Revolute 44" type="continuous">
    <origin rpy="0 0 0" xyz="-0.012497 0.01975 -0.007504"/>
    <parent link="new_motor_v2__1__1"/>
    <child link="big_U_self_v2__1__1"/>
    <axis xyz="0.0 -1.0 -0.0"/>
  </joint>
  <joint name="Rigid 45" type="fixed">
    <origin rpy="0 0 0" xyz="-1.5e-05 0.0 0.04"/>
    <parent link="big_U_self_v2__1__1"/>
    <child link="grap_base_v1_1"/>
  </joint>
  <joint name="Revolute 48" type="continuous">
    <origin rpy="0 0 0" xyz="-1.3e-05 0.0125 0.0355"/>
    <parent link="grap_base_v1_1"/>
    <child link="grap2_v2_1"/>
    <axis xyz="-1.0 -0.0 -0.00037"/>
  </joint>
  <joint name="Revolute 49" type="continuous">
    <origin rpy="0 0 0" xyz="-1.3e-05 -0.0125 0.0355"/>
    <parent link="grap_base_v1_1"/>
    <child link="grap2_v2_Mirror__1"/>
    <axis xyz="1.0 0.0 0.00037"/>
  </joint>
</robot>

