<?xml version="1.0" ?>
<!--===================================================================================-->
<!-- Autogenerated from v4.xacro -->
<!-- EDITING THIS FILE BY HAND IS NOT RECOMMENDED -->
<!--===================================================================================-->
<robot name="v4" xmlns:xacro="http://www.ros.org/wiki/xacro">
  <material name="silver">
    <color rgba="0.700 0.700 0.700 1.000"/>
  </material>
  <transmission name="Revolute 19_tran">
    <type>transmission_interface/SimpleTransmission</type>
    <joint name="Revolute 19">
      <hardwareInterface>hardware_interface/EffortJointInterface</hardwareInterface>
    </joint>
    <actuator name="Revolute 19_actr">
      <hardwareInterface>hardware_interface/EffortJointInterface</hardwareInterface>
      <mechanicalReduction>1</mechanicalReduction>
    </actuator>
  </transmission>
  <transmission name="Revolute 20_tran">
    <type>transmission_interface/SimpleTransmission</type>
    <joint name="Revolute 20">
      <hardwareInterface>hardware_interface/EffortJointInterface</hardwareInterface>
    </joint>
    <actuator name="Revolute 20_actr">
      <hardwareInterface>hardware_interface/EffortJointInterface</hardwareInterface>
      <mechanicalReduction>1</mechanicalReduction>
    </actuator>
  </transmission>
  <transmission name="Revolute 21_tran">
    <type>transmission_interface/SimpleTransmission</type>
    <joint name="Revolute 21">
      <hardwareInterface>hardware_interface/EffortJointInterface</hardwareInterface>
    </joint>
    <actuator name="Revolute 21_actr">
      <hardwareInterface>hardware_interface/EffortJointInterface</hardwareInterface>
      <mechanicalReduction>1</mechanicalReduction>
    </actuator>
  </transmission>
  <transmission name="Revolute 24_tran">
    <type>transmission_interface/SimpleTransmission</type>
    <joint name="Revolute 24">
      <hardwareInterface>hardware_interface/EffortJointInterface</hardwareInterface>
    </joint>
    <actuator name="Revolute 24_actr">
      <hardwareInterface>hardware_interface/EffortJointInterface</hardwareInterface>
      <mechanicalReduction>1</mechanicalReduction>
    </actuator>
  </transmission>
  <transmission name="Revolute 27_tran">
    <type>transmission_interface/SimpleTransmission</type>
    <joint name="Revolute 27">
      <hardwareInterface>hardware_interface/EffortJointInterface</hardwareInterface>
    </joint>
    <actuator name="Revolute 27_actr">
      <hardwareInterface>hardware_interface/EffortJointInterface</hardwareInterface>
      <mechanicalReduction>1</mechanicalReduction>
    </actuator>
  </transmission>
  <transmission name="Revolute 30_tran">
    <type>transmission_interface/SimpleTransmission</type>
    <joint name="Revolute 30">
      <hardwareInterface>hardware_interface/EffortJointInterface</hardwareInterface>
    </joint>
    <actuator name="Revolute 30_actr">
      <hardwareInterface>hardware_interface/EffortJointInterface</hardwareInterface>
      <mechanicalReduction>1</mechanicalReduction>
    </actuator>
  </transmission>
  <transmission name="Revolute 36_tran">
    <type>transmission_interface/SimpleTransmission</type>
    <joint name="Revolute 36">
      <hardwareInterface>hardware_interface/EffortJointInterface</hardwareInterface>
    </joint>
    <actuator name="Revolute 36_actr">
      <hardwareInterface>hardware_interface/EffortJointInterface</hardwareInterface>
      <mechanicalReduction>1</mechanicalReduction>
    </actuator>
  </transmission>
  <transmission name="Revolute 37_tran">
    <type>transmission_interface/SimpleTransmission</type>
    <joint name="Revolute 37">
      <hardwareInterface>hardware_interface/EffortJointInterface</hardwareInterface>
    </joint>
    <actuator name="Revolute 37_actr">
      <hardwareInterface>hardware_interface/EffortJointInterface</hardwareInterface>
      <mechanicalReduction>1</mechanicalReduction>
    </actuator>
  </transmission>
  <gazebo>
    <plugin filename="libgazebo_ros_control.so" name="control"/>
  </gazebo>
  <gazebo reference="base_link">
    <material>Gazebo/Silver</material>
    <mu1>0.2</mu1>
    <mu2>0.2</mu2>
    <selfCollide>true</selfCollide>
    <gravity>true</gravity>
  </gazebo>
  <gazebo reference="car_stand_v2_1">
    <material>Gazebo/Silver</material>
    <mu1>0.2</mu1>
    <mu2>0.2</mu2>
    <selfCollide>true</selfCollide>
  </gazebo>
  <gazebo reference="car_stand_v2__1__1">
    <material>Gazebo/Silver</material>
    <mu1>0.2</mu1>
    <mu2>0.2</mu2>
    <selfCollide>true</selfCollide>
  </gazebo>
  <gazebo reference="car_stand_v2__1___1___1__1">
    <material>Gazebo/Silver</material>
    <mu1>0.2</mu1>
    <mu2>0.2</mu2>
    <selfCollide>true</selfCollide>
  </gazebo>
  <gazebo reference="car_stand_2_v2_v1_1">
    <material>Gazebo/Silver</material>
    <mu1>0.2</mu1>
    <mu2>0.2</mu2>
    <selfCollide>true</selfCollide>
  </gazebo>
  <gazebo reference="car_stand_2_v2_v1__1__1">
    <material>Gazebo/Silver</material>
    <mu1>0.2</mu1>
    <mu2>0.2</mu2>
    <selfCollide>true</selfCollide>
  </gazebo>
  <gazebo reference="car_stand_2_v2_v1_2">
    <material>Gazebo/Silver</material>
    <mu1>0.2</mu1>
    <mu2>0.2</mu2>
    <selfCollide>true</selfCollide>
  </gazebo>
  <gazebo reference="car_wheel_v2_1">
    <material>Gazebo/Silver</material>
    <mu1>0.2</mu1>
    <mu2>0.2</mu2>
    <selfCollide>true</selfCollide>
  </gazebo>
  <gazebo reference="car_wheel_v2__1__1">
    <material>Gazebo/Silver</material>
    <mu1>0.2</mu1>
    <mu2>0.2</mu2>
    <selfCollide>true</selfCollide>
  </gazebo>
  <gazebo reference="car_wheel_v2__1__2">
    <material>Gazebo/Silver</material>
    <mu1>0.2</mu1>
    <mu2>0.2</mu2>
    <selfCollide>true</selfCollide>
  </gazebo>
  <gazebo reference="car_stand_v2__1___1__1">
    <material>Gazebo/Silver</material>
    <mu1>0.2</mu1>
    <mu2>0.2</mu2>
    <selfCollide>true</selfCollide>
  </gazebo>
  <gazebo reference="car_stand_2_v2_v1_4">
    <material>Gazebo/Silver</material>
    <mu1>0.2</mu1>
    <mu2>0.2</mu2>
    <selfCollide>true</selfCollide>
  </gazebo>
  <gazebo reference="car_wheel_v2__1___1__1">
    <material>Gazebo/Silver</material>
    <mu1>0.2</mu1>
    <mu2>0.2</mu2>
    <selfCollide>true</selfCollide>
  </gazebo>
  <gazebo reference="Side_U_Bracket_Component1_v2__1__1">
    <material>Gazebo/Silver</material>
    <mu1>0.2</mu1>
    <mu2>0.2</mu2>
    <selfCollide>true</selfCollide>
  </gazebo>
  <gazebo reference="new_motor_v2_1">
    <material>Gazebo/Silver</material>
    <mu1>0.2</mu1>
    <mu2>0.2</mu2>
    <selfCollide>true</selfCollide>
  </gazebo>
  <gazebo reference="big_U_self_v2_1">
    <material>Gazebo/Silver</material>
    <mu1>0.2</mu1>
    <mu2>0.2</mu2>
    <selfCollide>true</selfCollide>
  </gazebo>
  <gazebo reference="small_U_self_v3_v2_1">
    <material>Gazebo/Silver</material>
    <mu1>0.2</mu1>
    <mu2>0.2</mu2>
    <selfCollide>true</selfCollide>
  </gazebo>
  <gazebo reference="new_motor_v2__1__1">
    <material>Gazebo/Silver</material>
    <mu1>0.2</mu1>
    <mu2>0.2</mu2>
    <selfCollide>true</selfCollide>
  </gazebo>
  <gazebo reference="big_U_self_v2__1__1">
    <material>Gazebo/Silver</material>
    <mu1>0.2</mu1>
    <mu2>0.2</mu2>
    <selfCollide>true</selfCollide>
  </gazebo>
  <gazebo reference="grap_base_v1_1">
    <material>Gazebo/Silver</material>
    <mu1>0.2</mu1>
    <mu2>0.2</mu2>
    <selfCollide>true</selfCollide>
  </gazebo>
  <gazebo reference="grap2_v2_1">
    <material>Gazebo/Silver</material>
    <mu1>0.2</mu1>
    <mu2>0.2</mu2>
    <selfCollide>true</selfCollide>
  </gazebo>
  <gazebo reference="grap2_v2_Mirror__1">
    <material>Gazebo/Silver</material>
    <mu1>0.2</mu1>
    <mu2>0.2</mu2>
    <selfCollide>true</selfCollide>
  </gazebo>
  <link name="base_link">
    <inertial>
      <origin rpy="0 0 0" xyz="-0.03490559353136172 -0.0012908226787900414 0.05486728773240156"/>
      <mass value="40.856985871889826"/>
      <inertia ixx="0.201326" ixy="4.1e-05" ixz="-0.004755" iyy="0.334677" iyz="-0.00022" izz="0.444812"/>
    </inertial>
    <visual>
      <origin rpy="0 0 0" xyz="0 0 0"/>
      <geometry>
        <mesh filename="package://v4_description/meshes/base_link.stl" scale="0.001 0.001 0.001"/>
      </geometry>
      <material name="silver"/>
    </visual>
    <collision>
      <origin rpy="0 0 0" xyz="0 0 0"/>
      <geometry>
        <mesh filename="package://v4_description/meshes/base_link.stl" scale="0.001 0.001 0.001"/>
      </geometry>
    </collision>
  </link>
  <link name="car_stand_v2_1">
    <inertial>
      <origin rpy="0 0 0" xyz="0.03988993252380594 -0.0025004360304179962 -0.01795344297744809"/>
      <mass value="0.06574803361092448"/>
      <inertia ixx="1.6e-05" ixy="0.0" ixz="1.6e-05" iyy="5.4e-05" iyz="0.0" izz="3.7e-05"/>
    </inertial>
    <visual>
      <origin rpy="0 0 0" xyz="-0.044648 0.101416 -0.040924"/>
      <geometry>
        <mesh filename="package://v4_description/meshes/car_stand_v2_1.stl" scale="0.001 0.001 0.001"/>
      </geometry>
      <material name="silver"/>
    </visual>
    <collision>
      <origin rpy="0 0 0" xyz="-0.044648 0.101416 -0.040924"/>
      <geometry>
        <mesh filename="package://v4_description/meshes/car_stand_v2_1.stl" scale="0.001 0.001 0.001"/>
      </geometry>
    </collision>
  </link>
  <link name="car_stand_v2__1__1">
    <inertial>
      <origin rpy="0 0 0" xyz="0.03988993252381052 0.00249956396958205 -0.017953442977448077"/>
      <mass value="0.06574803361092448"/>
      <inertia ixx="1.6e-05" ixy="0.0" ixz="1.6e-05" iyy="5.4e-05" iyz="0.0" izz="3.7e-05"/>
    </inertial>
    <visual>
      <origin rpy="0 0 0" xyz="-0.044648 -0.098584 -0.040924"/>
      <geometry>
        <mesh filename="package://v4_description/meshes/car_stand_v2__1__1.stl" scale="0.001 0.001 0.001"/>
      </geometry>
      <material name="silver"/>
    </visual>
    <collision>
      <origin rpy="0 0 0" xyz="-0.044648 -0.098584 -0.040924"/>
      <geometry>
        <mesh filename="package://v4_description/meshes/car_stand_v2__1__1.stl" scale="0.001 0.001 0.001"/>
      </geometry>
    </collision>
  </link>
  <link name="car_stand_v2__1___1___1__1">
    <inertial>
      <origin rpy="0 0 0" xyz="-0.03989044739074814 -0.002500436030408615 -0.017953442977451526"/>
      <mass value="0.06574803361092448"/>
      <inertia ixx="1.6e-05" ixy="0.0" ixz="-1.6e-05" iyy="5.4e-05" iyz="0.0" izz="3.7e-05"/>
    </inertial>
    <visual>
      <origin rpy="0 0 0" xyz="0.11402 0.101416 -0.040924"/>
      <geometry>
        <mesh filename="package://v4_description/meshes/car_stand_v2__1___1___1__1.stl" scale="0.001 0.001 0.001"/>
      </geometry>
      <material name="silver"/>
    </visual>
    <collision>
      <origin rpy="0 0 0" xyz="0.11402 0.101416 -0.040924"/>
      <geometry>
        <mesh filename="package://v4_description/meshes/car_stand_v2__1___1___1__1.stl" scale="0.001 0.001 0.001"/>
      </geometry>
    </collision>
  </link>
  <link name="car_stand_2_v2_v1_1">
    <inertial>
      <origin rpy="0 0 0" xyz="0.008838668542350672 0.0024995639695819527 -0.008839293755308316"/>
      <mass value="0.025649195499023388"/>
      <inertia ixx="1e-06" ixy="0.0" ixz="0.0" iyy="3e-06" iyz="0.0" izz="1e-06"/>
    </inertial>
    <visual>
      <origin rpy="0 0 0" xyz="-0.100582 0.101416 -0.005915"/>
      <geometry>
        <mesh filename="package://v4_description/meshes/car_stand_2_v2_v1_1.stl" scale="0.001 0.001 0.001"/>
      </geometry>
      <material name="silver"/>
    </visual>
    <collision>
      <origin rpy="0 0 0" xyz="-0.100582 0.101416 -0.005915"/>
      <geometry>
        <mesh filename="package://v4_description/meshes/car_stand_2_v2_v1_1.stl" scale="0.001 0.001 0.001"/>
      </geometry>
    </collision>
  </link>
  <link name="car_stand_2_v2_v1__1__1">
    <inertial>
      <origin rpy="0 0 0" xyz="-0.008839331457644747 -0.002500436030418024 -0.008839293755307998"/>
      <mass value="0.025649195499023388"/>
      <inertia ixx="1e-06" ixy="0.0" ixz="0.0" iyy="3e-06" iyz="0.0" izz="1e-06"/>
    </inertial>
    <visual>
      <origin rpy="0 0 0" xyz="-0.11826 -0.098584 -0.005915"/>
      <geometry>
        <mesh filename="package://v4_description/meshes/car_stand_2_v2_v1__1__1.stl" scale="0.001 0.001 0.001"/>
      </geometry>
      <material name="silver"/>
    </visual>
    <collision>
      <origin rpy="0 0 0" xyz="-0.11826 -0.098584 -0.005915"/>
      <geometry>
        <mesh filename="package://v4_description/meshes/car_stand_2_v2_v1__1__1.stl" scale="0.001 0.001 0.001"/>
      </geometry>
    </collision>
  </link>
  <link name="car_stand_2_v2_v1_2">
    <inertial>
      <origin rpy="0 0 0" xyz="0.0088388165906792 0.002499563969585103 -0.008839293755313506"/>
      <mass value="0.025649195499023388"/>
      <inertia ixx="1e-06" ixy="-0.0" ixz="0.0" iyy="3e-06" iyz="0.0" izz="1e-06"/>
    </inertial>
    <visual>
      <origin rpy="0 0 0" xyz="0.187632 0.101416 -0.005915"/>
      <geometry>
        <mesh filename="package://v4_description/meshes/car_stand_2_v2_v1_2.stl" scale="0.001 0.001 0.001"/>
      </geometry>
      <material name="silver"/>
    </visual>
    <collision>
      <origin rpy="0 0 0" xyz="0.187632 0.101416 -0.005915"/>
      <geometry>
        <mesh filename="package://v4_description/meshes/car_stand_2_v2_v1_2.stl" scale="0.001 0.001 0.001"/>
      </geometry>
    </collision>
  </link>
  <link name="car_wheel_v2_1">
    <inertial>
      <origin rpy="0 0 0" xyz="-1.834093510677537e-07 -0.02381625276238626 -2.9375528741654514e-07"/>
      <mass value="0.7168827451003499"/>
      <inertia ixx="0.000271" ixy="-0.0" ixz="-0.0" iyy="0.000476" iyz="0.0" izz="0.000271"/>
    </inertial>
    <visual>
      <origin rpy="0 0 0" xyz="0.178793 0.106416 0.002924"/>
      <geometry>
        <mesh filename="package://v4_description/meshes/car_wheel_v2_1.stl" scale="0.001 0.001 0.001"/>
      </geometry>
      <material name="silver"/>
    </visual>
    <collision>
      <origin rpy="0 0 0" xyz="0.178793 0.106416 0.002924"/>
      <geometry>
        <mesh filename="package://v4_description/meshes/car_wheel_v2_1.stl" scale="0.001 0.001 0.001"/>
      </geometry>
    </collision>
  </link>
  <link name="car_wheel_v2__1__1">
    <inertial>
      <origin rpy="0 0 0" xyz="-3.314576812324388e-07 -0.02381625276238937 -2.9375528393148567e-07"/>
      <mass value="0.7168827451003499"/>
      <inertia ixx="0.000271" ixy="-0.0" ixz="-0.0" iyy="0.000476" iyz="0.0" izz="0.000271"/>
    </inertial>
    <visual>
      <origin rpy="0 0 0" xyz="-0.109421 0.106416 0.002924"/>
      <geometry>
        <mesh filename="package://v4_description/meshes/car_wheel_v2__1__1.stl" scale="0.001 0.001 0.001"/>
      </geometry>
      <material name="silver"/>
    </visual>
    <collision>
      <origin rpy="0 0 0" xyz="-0.109421 0.106416 0.002924"/>
      <geometry>
        <mesh filename="package://v4_description/meshes/car_wheel_v2__1__1.stl" scale="0.001 0.001 0.001"/>
      </geometry>
    </collision>
  </link>
  <link name="car_wheel_v2__1__2">
    <inertial>
      <origin rpy="0 0 0" xyz="-3.3145767672215776e-07 0.0238153807015533 -2.9375533295607215e-07"/>
      <mass value="0.7168827451003499"/>
      <inertia ixx="0.000271" ixy="0.0" ixz="0.0" iyy="0.000476" iyz="0.0" izz="0.000271"/>
    </inertial>
    <visual>
      <origin rpy="0 0 0" xyz="-0.109421 -0.103584 0.002924"/>
      <geometry>
        <mesh filename="package://v4_description/meshes/car_wheel_v2__1__2.stl" scale="0.001 0.001 0.001"/>
      </geometry>
      <material name="silver"/>
    </visual>
    <collision>
      <origin rpy="0 0 0" xyz="-0.109421 -0.103584 0.002924"/>
      <geometry>
        <mesh filename="package://v4_description/meshes/car_wheel_v2__1__2.stl" scale="0.001 0.001 0.001"/>
      </geometry>
    </collision>
  </link>
  <link name="car_stand_v2__1___1__1">
    <inertial>
      <origin rpy="0 0 0" xyz="-0.03989044739074339 0.0024995639695852695 -0.017953442977451568"/>
      <mass value="0.06574803361092448"/>
      <inertia ixx="1.6e-05" ixy="0.0" ixz="-1.6e-05" iyy="5.4e-05" iyz="-0.0" izz="3.7e-05"/>
    </inertial>
    <visual>
      <origin rpy="0 0 0" xyz="0.11402 -0.098584 -0.040924"/>
      <geometry>
        <mesh filename="package://v4_description/meshes/car_stand_v2__1___1__1.stl" scale="0.001 0.001 0.001"/>
      </geometry>
      <material name="silver"/>
    </visual>
    <collision>
      <origin rpy="0 0 0" xyz="0.11402 -0.098584 -0.040924"/>
      <geometry>
        <mesh filename="package://v4_description/meshes/car_stand_v2__1___1__1.stl" scale="0.001 0.001 0.001"/>
      </geometry>
    </collision>
  </link>
  <link name="car_stand_2_v2_v1_4">
    <inertial>
      <origin rpy="0 0 0" xyz="0.00883881659068353 -0.002500436030414721 -0.00883929375531351"/>
      <mass value="0.025649195499023388"/>
      <inertia ixx="1e-06" ixy="0.0" ixz="0.0" iyy="3e-06" iyz="0.0" izz="1e-06"/>
    </inertial>
    <visual>
      <origin rpy="0 0 0" xyz="0.187632 -0.098584 -0.005915"/>
      <geometry>
        <mesh filename="package://v4_description/meshes/car_stand_2_v2_v1_4.stl" scale="0.001 0.001 0.001"/>
      </geometry>
      <material name="silver"/>
    </visual>
    <collision>
      <origin rpy="0 0 0" xyz="0.187632 -0.098584 -0.005915"/>
      <geometry>
        <mesh filename="package://v4_description/meshes/car_stand_2_v2_v1_4.stl" scale="0.001 0.001 0.001"/>
      </geometry>
    </collision>
  </link>
  <link name="car_wheel_v2__1___1__1">
    <inertial>
      <origin rpy="0 0 0" xyz="-1.834093467378839e-07 0.02381538070155663 -2.937553364771271e-07"/>
      <mass value="0.7168827451003499"/>
      <inertia ixx="0.000271" ixy="0.0" ixz="0.0" iyy="0.000476" iyz="0.0" izz="0.000271"/>
    </inertial>
    <visual>
      <origin rpy="0 0 0" xyz="0.178793 -0.103584 0.002924"/>
      <geometry>
        <mesh filename="package://v4_description/meshes/car_wheel_v2__1___1__1.stl" scale="0.001 0.001 0.001"/>
      </geometry>
      <material name="silver"/>
    </visual>
    <collision>
      <origin rpy="0 0 0" xyz="0.178793 -0.103584 0.002924"/>
      <geometry>
        <mesh filename="package://v4_description/meshes/car_wheel_v2__1___1__1.stl" scale="0.001 0.001 0.001"/>
      </geometry>
    </collision>
  </link>
  <link name="Side_U_Bracket_Component1_v2__1__1">
    <inertial>
      <origin rpy="0 0 0" xyz="-0.002196396463554351 -4.360305858636289e-07 -8.453993113072267e-05"/>
      <mass value="0.02951040982880665"/>
      <inertia ixx="1.1e-05" ixy="0.0" ixz="-0.0" iyy="4e-06" iyz="-0.0" izz="7e-06"/>
    </inertial>
    <visual>
      <origin rpy="0 0 0" xyz="0.184696 0.001416 -0.063262"/>
      <geometry>
        <mesh filename="package://v4_description/meshes/Side_U_Bracket_Component1_v2__1__1.stl" scale="0.001 0.001 0.001"/>
      </geometry>
      <material name="silver"/>
    </visual>
    <collision>
      <origin rpy="0 0 0" xyz="0.184696 0.001416 -0.063262"/>
      <geometry>
        <mesh filename="package://v4_description/meshes/Side_U_Bracket_Component1_v2__1__1.stl" scale="0.001 0.001 0.001"/>
      </geometry>
    </collision>
  </link>
  <link name="new_motor_v2_1">
    <inertial>
      <origin rpy="0 0 0" xyz="-0.007452485743466214 -0.022427186385094992 0.017654066718774016"/>
      <mass value="0.20364393858439991"/>
      <inertia ixx="5.1e-05" ixy="-0.0" ixz="-0.0" iyy="3.5e-05" iyz="-0.0" izz="3e-05"/>
    </inertial>
    <visual>
      <origin rpy="0 0 0" xyz="0.192009 -0.018834 -0.045728"/>
      <geometry>
        <mesh filename="package://v4_description/meshes/new_motor_v2_1.stl" scale="0.001 0.001 0.001"/>
      </geometry>
      <material name="silver"/>
    </visual>
    <collision>
      <origin rpy="0 0 0" xyz="0.192009 -0.018834 -0.045728"/>
      <geometry>
        <mesh filename="package://v4_description/meshes/new_motor_v2_1.stl" scale="0.001 0.001 0.001"/>
      </geometry>
    </collision>
  </link>
  <link name="big_U_self_v2_1">
    <inertial>
      <origin rpy="0 0 0" xyz="-0.02423781962657942 -4.360255596357141e-07 -9.331276065296934e-06"/>
      <mass value="0.041847447766480916"/>
      <inertia ixx="2.4e-05" ixy="0.0" ixz="-0.0" iyy="1.1e-05" iyz="0.0" izz="3.2e-05"/>
    </inertial>
    <visual>
      <origin rpy="0 0 0" xyz="0.199519 0.000916 -0.073226"/>
      <geometry>
        <mesh filename="package://v4_description/meshes/big_U_self_v2_1.stl" scale="0.001 0.001 0.001"/>
      </geometry>
      <material name="silver"/>
    </visual>
    <collision>
      <origin rpy="0 0 0" xyz="0.199519 0.000916 -0.073226"/>
      <geometry>
        <mesh filename="package://v4_description/meshes/big_U_self_v2_1.stl" scale="0.001 0.001 0.001"/>
      </geometry>
    </collision>
  </link>
  <link name="small_U_self_v3_v2_1">
    <inertial>
      <origin rpy="0 0 0" xyz="-0.009287793098572444 -0.0005387943235771196 -3.591936350147429e-06"/>
      <mass value="0.025534175468152884"/>
      <inertia ixx="9e-06" ixy="-0.0" ixz="-0.0" iyy="3e-06" iyz="-0.0" izz="1e-05"/>
    </inertial>
    <visual>
      <origin rpy="0 0 0" xyz="0.239519 0.000916 -0.073211"/>
      <geometry>
        <mesh filename="package://v4_description/meshes/small_U_self_v3_v2_1.stl" scale="0.001 0.001 0.001"/>
      </geometry>
      <material name="silver"/>
    </visual>
    <collision>
      <origin rpy="0 0 0" xyz="0.239519 0.000916 -0.073211"/>
      <geometry>
        <mesh filename="package://v4_description/meshes/small_U_self_v3_v2_1.stl" scale="0.001 0.001 0.001"/>
      </geometry>
    </collision>
  </link>
  <link name="new_motor_v2__1__1">
    <inertial>
      <origin rpy="0 0 0" xyz="-0.01796902636035358 0.021971771959281163 -0.008360549860558564"/>
      <mass value="0.20364667946656756"/>
      <inertia ixx="3e-05" ixy="-0.0" ixz="-0.0" iyy="3.5e-05" iyz="-0.0" izz="5.1e-05"/>
    </inertial>
    <visual>
      <origin rpy="0 0 0" xyz="0.252022 0.021166 -0.080706"/>
      <geometry>
        <mesh filename="package://v4_description/meshes/new_motor_v2__1__1.stl" scale="0.001 0.001 0.001"/>
      </geometry>
      <material name="silver"/>
    </visual>
    <collision>
      <origin rpy="0 0 0" xyz="0.252022 0.021166 -0.080706"/>
      <geometry>
        <mesh filename="package://v4_description/meshes/new_motor_v2__1__1.stl" scale="0.001 0.001 0.001"/>
      </geometry>
    </collision>
  </link>
  <link name="big_U_self_v2__1__1">
    <inertial>
      <origin rpy="0 0 0" xyz="-0.024234621373399545 -0.0003468056978262182 -9.007546020775581e-06"/>
      <mass value="0.04184744776648061"/>
      <inertia ixx="2.4e-05" ixy="0.0" ixz="-0.0" iyy="1.1e-05" iyz="0.0" izz="3.2e-05"/>
    </inertial>
    <visual>
      <origin rpy="0 0 0" xyz="0.279796 0.002011 -0.072396"/>
      <geometry>
        <mesh filename="package://v4_description/meshes/big_U_self_v2__1__1.stl" scale="0.001 0.001 0.001"/>
      </geometry>
      <material name="silver"/>
    </visual>
    <collision>
      <origin rpy="0 0 0" xyz="0.279796 0.002011 -0.072396"/>
      <geometry>
        <mesh filename="package://v4_description/meshes/big_U_self_v2__1__1.stl" scale="0.001 0.001 0.001"/>
      </geometry>
    </collision>
  </link>
  <link name="grap_base_v1_1">
    <inertial>
      <origin rpy="0 0 0" xyz="-0.014566952255857912 -0.00020826804762141176 -5.219548716600686e-06"/>
      <mass value="0.15189124788812738"/>
      <inertia ixx="9.5e-05" ixy="0.0" ixz="0.0" iyy="9.3e-05" iyz="0.0" izz="6.1e-05"/>
    </inertial>
    <visual>
      <origin rpy="0 0 0" xyz="0.319792 0.002583 -0.072381"/>
      <geometry>
        <mesh filename="package://v4_description/meshes/grap_base_v1_1.stl" scale="0.001 0.001 0.001"/>
      </geometry>
      <material name="silver"/>
    </visual>
    <collision>
      <origin rpy="0 0 0" xyz="0.319792 0.002583 -0.072381"/>
      <geometry>
        <mesh filename="package://v4_description/meshes/grap_base_v1_1.stl" scale="0.001 0.001 0.001"/>
      </geometry>
    </collision>
  </link>
  <link name="grap2_v2_1">
    <inertial>
      <origin rpy="0 0 0" xyz="-0.03291400371766562 0.005117554961966184 0.0011004146243947382"/>
      <mass value="0.04062678364093081"/>
      <inertia ixx="3e-06" ixy="-0.0" ixz="2e-06" iyy="2.6e-05" iyz="0.0" izz="2.7e-05"/>
    </inertial>
    <visual>
      <origin rpy="0 0 0" xyz="0.355467 -0.009408 -0.072368"/>
      <geometry>
        <mesh filename="package://v4_description/meshes/grap2_v2_1.stl" scale="0.001 0.001 0.001"/>
      </geometry>
      <material name="silver"/>
    </visual>
    <collision>
      <origin rpy="0 0 0" xyz="0.355467 -0.009408 -0.072368"/>
      <geometry>
        <mesh filename="package://v4_description/meshes/grap2_v2_1.stl" scale="0.001 0.001 0.001"/>
      </geometry>
    </collision>
  </link>
  <link name="grap2_v2_Mirror__1">
    <inertial>
      <origin rpy="0 0 0" xyz="-0.032755044017192425 -0.006055892134894434 0.0011006057396234226"/>
      <mass value="0.04062678364093082"/>
      <inertia ixx="3e-06" ixy="-0.0" ixz="2e-06" iyy="2.6e-05" iyz="-0.0" izz="2.7e-05"/>
    </inertial>
    <visual>
      <origin rpy="0 0 0" xyz="0.355109 0.015589 -0.072368"/>
      <geometry>
        <mesh filename="package://v4_description/meshes/grap2_v2_Mirror__1.stl" scale="0.001 0.001 0.001"/>
      </geometry>
      <material name="silver"/>
    </visual>
    <collision>
      <origin rpy="0 0 0" xyz="0.355109 0.015589 -0.072368"/>
      <geometry>
        <mesh filename="package://v4_description/meshes/grap2_v2_Mirror__1.stl" scale="0.001 0.001 0.001"/>
      </geometry>
    </collision>
  </link>
  <joint name="Rigid 11" type="fixed">
    <origin rpy="0 0 0" xyz="0.044648 -0.101416 0.040924"/>
    <parent link="base_link"/>
    <child link="car_stand_v2_1"/>
  </joint>
  <joint name="Rigid 12" type="fixed">
    <origin rpy="0 0 0" xyz="0.044648 0.098584 0.040924"/>
    <parent link="base_link"/>
    <child link="car_stand_v2__1__1"/>
  </joint>
  <joint name="Rigid 14" type="fixed">
    <origin rpy="0 0 0" xyz="-0.11402 -0.101416 0.040924"/>
    <parent link="base_link"/>
    <child link="car_stand_v2__1___1___1__1"/>
  </joint>
  <joint name="Rigid 15" type="fixed">
    <origin rpy="0 0 0" xyz="0.055934 0.0 -0.035009"/>
    <parent link="car_stand_v2_1"/>
    <child link="car_stand_2_v2_v1_1"/>
  </joint>
  <joint name="Rigid 16" type="fixed">
    <origin rpy="0 0 0" xyz="0.073612 0.0 -0.035009"/>
    <parent link="car_stand_v2__1__1"/>
    <child link="car_stand_2_v2_v1__1__1"/>
  </joint>
  <joint name="Rigid 17" type="fixed">
    <origin rpy="0 0 0" xyz="-0.073612 0.0 -0.035009"/>
    <parent link="car_stand_v2__1___1___1__1"/>
    <child link="car_stand_2_v2_v1_2"/>
  </joint>
  <joint name="Revolute 19" type="continuous">
    <origin rpy="0 0 0" xyz="-0.064773 -0.005 -0.043848"/>
    <parent link="car_stand_v2__1___1___1__1"/>
    <child link="car_wheel_v2_1"/>
    <axis xyz="-0.0 -1.0 0.0"/>
  </joint>
  <joint name="Revolute 20" type="continuous">
    <origin rpy="0 0 0" xyz="0.064773 -0.005 -0.043848"/>
    <parent link="car_stand_v2_1"/>
    <child link="car_wheel_v2__1__1"/>
    <axis xyz="-0.0 -1.0 0.0"/>
  </joint>
  <joint name="Revolute 21" type="continuous">
    <origin rpy="0 0 0" xyz="0.064773 0.005 -0.043848"/>
    <parent link="car_stand_v2__1__1"/>
    <child link="car_wheel_v2__1__2"/>
    <axis xyz="-0.0 -1.0 0.0"/>
  </joint>
  <joint name="Rigid 22" type="fixed">
    <origin rpy="0 0 0" xyz="-0.11402 0.098584 0.040924"/>
    <parent link="base_link"/>
    <child link="car_stand_v2__1___1__1"/>
  </joint>
  <joint name="Rigid 23" type="fixed">
    <origin rpy="0 0 0" xyz="-0.073612 0.0 -0.035009"/>
    <parent link="car_stand_v2__1___1__1"/>
    <child link="car_stand_2_v2_v1_4"/>
  </joint>
  <joint name="Revolute 24" type="continuous">
    <origin rpy="0 -1.57079632679 0" xyz="-0.064773 0.005 -0.043848"/>
    <parent link="car_stand_v2__1___1__1"/>
    <child link="car_wheel_v2__1___1__1"/>
    <axis xyz="-0.0 -1.0 0.0"/>
  </joint>
  <joint name="Rigid 25" type="fixed">
    <origin rpy="0 0 0" xyz="-0.184696 -0.001416 0.063262"/>
    <parent link="base_link"/>
    <child link="Side_U_Bracket_Component1_v2__1__1"/>
  </joint>
  <joint name="Rigid 26" type="fixed">
    <origin rpy="0 0 0" xyz="-0.007313 0.02025 -0.017534"/>
    <parent link="Side_U_Bracket_Component1_v2__1__1"/>
    <child link="new_motor_v2_1"/>
  </joint>
  <joint name="Revolute 27" type="continuous">
    <origin rpy="0 0 0" xyz="-0.00751 -0.01975 0.027498"/>
    <parent link="new_motor_v2_1"/>
    <child link="big_U_self_v2_1"/>
    <axis xyz="-0.0 -1.0 0.0"/>
  </joint>
  <joint name="Rigid 28" type="fixed">
    <origin rpy="0 0 0" xyz="-0.04 0.0 -1.5e-05"/>
    <parent link="big_U_self_v2_1"/>
    <child link="small_U_self_v3_v2_1"/>
  </joint>
  <joint name="Rigid 29" type="fixed">
    <origin rpy="0 0 0" xyz="-0.012503 -0.02025 0.007495"/>
    <parent link="small_U_self_v3_v2_1"/>
    <child link="new_motor_v2__1__1"/>
  </joint>
  <joint name="Revolute 30" type="continuous">
    <origin rpy="0 0 0" xyz="-0.027774 0.019155 -0.00831"/>
    <parent link="new_motor_v2__1__1"/>
    <child link="big_U_self_v2__1__1"/>
    <axis xyz="0.014291 -0.999898 5e-06"/>
  </joint>
  <joint name="Rigid 31" type="fixed">
    <origin rpy="0 0 0" xyz="-0.039996 -0.000572 -1.5e-05"/>
    <parent link="big_U_self_v2__1__1"/>
    <child link="grap_base_v1_1"/>
  </joint>
  <joint name="Revolute 36" type="continuous">
    <origin rpy="0 0 0" xyz="-0.035675 0.011991 -1.3e-05"/>
    <parent link="grap_base_v1_1"/>
    <child link="grap2_v2_1"/>
    <axis xyz="-0.00037 0.0 1.0"/>
  </joint>
  <joint name="Revolute 37" type="continuous">
    <origin rpy="0 0 0" xyz="-0.035317 -0.013006 -1.3e-05"/>
    <parent link="grap_base_v1_1"/>
    <child link="grap2_v2_Mirror__1"/>
    <axis xyz="-0.00037 0.0 1.0"/>
  </joint>
</robot>

